Workbook

Sheet lezione
A1: Today | B1: 45748 | E1: ZCB | H1: Coupon bond with maturity 1 ott 27 | N1: Coupon bond with maturity 1 lug 28
A3: Coupon | B3: Maturity | C3: Price | E3: Time to maturity (T) | F3: p(0,T) | G3: i(0,T) | H3: Dates | I3: 45931 | J3: 46113 | K3: 46296 | L3: 46478 | M3: 46661 | N3: Dates | O3: 45839 | P3: 46023 | Q3: 46204 | R3: 46388 | S3: 46569 | T3: 46753 | U3: 46935
A4: no | B4: 45778 | C4: 99.99874 | E4: =1/12 -> 0.083333333 | F4: =C4/100 -> 0.9999874 | G4: =F4^(-1/E4)-1 -> 0.00015121238 | H4: Time to mat | I4: 0.5 | J4: 1 | K4: 1.5 | L4: 2 | M4: 2.5 | N4: Time to mat (T) | O4: =3/12 -> 0.25 | P4: =O4+0.5 -> 0.75 | Q4: =P4+0.5 -> 1.25 | R4: =Q4+0.5 -> 1.75 | S4: =R4+0.5 -> 2.25 | T4: =S4+0.5 -> 2.75 | U4: =T4+0.5 -> 3.25
A5: no | B5: 45901 | C5: 99.825 | E5: =5/12 -> 0.41666667 | F5: =C5/100 -> 0.99825 | G5: =F5^(-1/E5)-1 -> 0.0042125271 | H5: Payments | I5: 1.35 | J5: 1.35 | K5: 1.35 | L5: 1.35 | M5: 101.35 | N5: Payments | O5: 0.25 | P5: 0.25 | Q5: 0.25 | R5: 0.25 | S5: 0.25 | T5: 0.25 | U5: 100.25
A6: no | B6: 45931 | C6: 99.7079 | E6: =6/12 -> 0.5 | F6: =C6/100 -> 0.997079 | G6: =F6^(-1/E6)-1 -> 0.0058676968 | H6: Disc Val | I6: =I5*(1+G6)^(-I4) -> 1.3460566 | J6: Interpolation | M6: unknown | N6: i(0,T) | O6: =((E5-O4)*G4+(O4-E4)*G5)/(E5-E4) -> 0.0021818698 | P6: =G7 -> 0.013036279 | Q6: =(($E9-Q4)*$G8+(Q4-$E8)*$G9)/($E9-$E8) -> 0.020508654 | R6: =(($E9-R4)*$G8+(R4-$E8)*$G9)/($E9-$E8) -> 0.022032121 | S6: =(($E9-S4)*$G8+(S4-$E8)*$G9)/($E9-$E8) -> 0.023555587 | T6: Interpol | U6: unknown
A7: no | B7: 46023 | C7: 99.0333 | E7: =9/12 -> 0.75 | F7: =C7/100 -> 0.990333 | G7: =F7^(-1/E7)-1 -> 0.013036279 | N7: DiscVal | O7: =O5*(1+O6)^(-O4) -> 0.24986382 | P7: =P5*(1+P6)^(-P4) -> 0.24758325 | Q7: =Q5*(1+Q6)^(-Q4) -> 0.2437357 | R7: =R5*(1+R6)^(-R4) -> 0.24064512 | S7: =S5*(1+S6)^(-S4) -> 0.23724075
A8: no | B8: 46082 | C8: 98.2459 | E8: =11/12 -> 0.91666667 | F8: =C8/100 -> 0.982459 | G8: =F8^(-1/E8)-1 -> 0.01949301 | H8: i(0,0.92) | I8: =E8 -> 0.91666667 | J8: =G8 -> 0.01949301
A9: 0.027 | B9: 46661 | C9: 100.71 | E9: =2.5 -> 2.5 | G9: =L11 -> 0.02431732 | H9: i(0,2.5) | I9: 2.5 | J9: 0.02431732 | K9: unknown | O9: i(0,2.5) | P9: 2.5 | Q9: =G9 -> 0.02431732
A10: 0.005 | B10: 46935 | C10: 93.67 | E10: =3.25 -> 3.25 | G10: =Q10 -> 0.025604088 | H10: T | I10: 1 | J10: 1.5 | K10: 2 | L10: 2.5 | O10: i(0,3.25) | P10: 3.25 | Q10: 0.025604088 | S10: unknown
H11: i(0,T) | I11: =(($I$9-I10)*$J$8+(I10-$I$8)*$J$9)/($I$9-$I$8) -> 0.019746921 | J11: =(($I$9-J10)*$J$8+(J10-$I$8)*$J$9)/($I$9-$I$8) -> 0.021270387 | K11: =(($I$9-K10)*$J$8+(K10-$I$8)*$J$9)/($I$9-$I$8) -> 0.022793854 | L11: =(($I$9-L10)*$J$8+(L10-$I$8)*$J$9)/($I$9-$I$8) -> 0.02431732 | O11: T | P11: 2.75 | Q11: 3.25
H12: Disc Val | I12: =J5*(1+I11)^(-I10) -> 1.3238579 | J12: =K5*(1+J11)^(-J10) -> 1.3080449 | K12: =L5*(1+K11)^(-K10) -> 1.2904986 | L12: =M5*(1+L11)^(-L10) -> 95.441545 | O12: i(0,T) | P12: =(($P$10-P11)*$Q$9+(P11-$P$9)*$Q$10)/($P$10-$P$9) -> 0.024746243 | Q12: =(($P$10-Q11)*$Q$9+(Q11-$P$9)*$Q$10)/($P$10-$P$9) -> 0.025604088
O13: DiscVal | P13: =T5*(1+P12)^(-P11) -> 0.23374648 | Q13: =U5*(1+Q12)^(-Q11) -> 92.3422
I14: Discounted price | J14: =SUM(I6,I12:L12) -> 100.71
I15: Market Price | J15: 100.71 | O15: Discounted Price | Q15: =SUM(O7:S7,P13:Q13) -> 93.795015
O16: Market Price | Q16: =C10 -> 93.67
I17: Looking for J9 such that J14=J15 | L17: Difference | M17: =J15-J14 -> -3.330175e-06 | O17: Accrual | Q17: 0.125
S18: Difference | T18: =Q15-(Q16+Q17) -> 1.4715827e-05
B23: T | C23: i(0,T)
B24: =1/12 -> 0.083333333 | C24: 0.00015121238
B25: =5/12 -> 0.41666667 | C25: 0.0042125271
B26: =6/12 -> 0.5 | C26: 0.0058676968
B27: =9/12 -> 0.75 | C27: 0.013036279
B28: =11/12 -> 0.91666667 | C28: 0.01949301
B29: 2.75 | C29: 0.024746243
B30: =3.25 -> 3.25 | C30: 0.025604088

Sheet punto 1-2-3
A1: Today | B1: 45748 | E1: ZCB | I1: Coupon bond with maturity 1 apr 27
A3: Coupon | B3: Maturity | C3: Price | E3: Time to maturity (T) | F3: p(0,T) | G3: i(0,T) | I3: Dates | J3: 45931 | K3: 46113 | L3: 46296 | M3: 46478
A4: no | B4: 45778 | C4: 99.99874 | E4: 0.083333333 | F4: 0.9999874 | G4: 0.00015121238 | I4: Time to mat | J4: 0.5 | K4: 1 | L4: 1.5 | M4: 2
A5: no | B5: 45901 | C5: 99.825 | E5: 0.41666667 | F5: 0.99825 | G5: 0.0042125271 | I5: Payments | J5: 1 | K5: 1 | L5: 1 | M5: 101
A6: no | B6: 45931 | C6: 99.7079 | E6: 0.5 | F6: 0.997079 | G6: 0.0058676968 | I6: Disc Val | J6: =J5*(1+G6)^(-J4) -> 0.997079
A7: no | B7: 46023 | C7: 99.0333 | E7: 0.75 | F7: 0.990333 | G7: 0.013036279
A8: no | B8: 46082 | C8: 98.2459 | E8: 0.91666667 | F8: 0.982459 | G8: 0.01949301 | I8: i(0,0.92) | J8: =E8 -> 0.91666667 | K8: =G8 -> 0.01949301
A9: 0.02 | B9: 46478 | C9: =K15 -> 99.495053 | E9: 2 | G9: =L11 -> 0.022793854 | I9: i(0,2.5) | J9: =E10 -> 2.5 | K9: =G10 -> 0.02431732
A10: 0.027 | B10: 46661 | C10: 100.71 | E10: 2.5 | G10: 0.02431732 | I10: T | J10: 1 | K10: 1.5 | L10: 2
A11: 0.005 | B11: 46935 | C11: 93.67 | E11: 3.25 | G11: 0.025604088 | I11: i(0,T) | J11: =(($J$9-J10)*$K$8+(J10-$J$8)*$K$9)/($J$9-$J$8) -> 0.019746921 | K11: =(($J$9-K10)*$K$8+(K10-$J$8)*$K$9)/($J$9-$J$8) -> 0.021270387 | L11: =(($J$9-L10)*$K$8+(L10-$J$8)*$K$9)/($J$9-$J$8) -> 0.022793854
I12: Disc Val | J12: =K5*(1+J11)^(-J10) -> 0.98063547 | K12: =L5*(1+K11)^(-K10) -> 0.96892217 | L12: =M5*(1+L11)^(-L10) -> 96.548416
J14: Discounted price | K14: =SUM(J6,J12:L12) -> 99.495053
B15: curva dei tassi | C15: market price | D15: variazione | J15: Market Price | K15: =K14 -> 99.495053
B16: i(0,t) | C16: =C9 -> 99.495053 | D16: -
B17: i(0,t) + 0,02% | C17: =K35 -> 99.456729 | D17: =C17-C16 -> -0.038323584
B18: i(0,t) - 0,02% | C18: =K51 -> 99.533399 | D18: =C18-C16 -> 0.038345979
A23: aumento della curva dei tassi | I23: Dates | J23: 45931 | K23: 46113 | L23: 46296 | M23: 46478
A24: t | B24: i(0,t) | C24: i(0,t) + 0.02% | I24: Time to mat | J24: 0.5 | K24: 1 | L24: 1.5 | M24: 2
A25: 0.083333333 | B25: =G4 -> 0.00015121238 | C25: =B25+0.02% -> 0.00035121238 | I25: Payments | J25: 1 | K25: 1 | L25: 1 | M25: 101
A26: 0.41666667 | B26: =G5 -> 0.0042125271 | C26: =B26+0.02% -> 0.0044125271 | I26: Disc Val | J26: =J25*(1+C27)^(-J24) -> 0.99697989
A27: 0.5 | B27: =G6 -> 0.0058676968 | C27: =B27+0.02% -> 0.0060676968
A28: 0.75 | B28: =G7 -> 0.013036279 | C28: =B28+0.02% -> 0.013236279 | I28: i(0,0.92) | J28: =E8 -> 0.91666667 | K28: =C29 -> 0.01969301
A29: 0.91666667 | B29: =G8 -> 0.01949301 | C29: =B29+0.02% -> 0.01969301 | I29: i(0,2.5) | J29: =E10 -> 2.5 | K29: =C33 -> 0.02451732
A30: 1 | B30: =J11 -> 0.019746921 | C30: =J31 -> 0.019946921 | I30: T | J30: 1 | K30: 1.5 | L30: 2
A31: 1.5 | B31: =K11 -> 0.021270387 | C31: =K31 -> 0.021470387 | I31: i(0,T) | J31: =(($J$29-J30)*$K$28+(J30-$J$28)*$K$29)/($J$29-$J$28) -> 0.019946921 | K31: =(($J$29-K30)*$K$28+(K30-$J$28)*$K$29)/($J$29-$J$28) -> 0.021470387 | L31: =(($J$29-L30)*$K$28+(L30-$J$28)*$K$29)/($J$29-$J$28) -> 0.022993854
A32: 2 | B32: =G9 -> 0.022793854 | C32: =B32+0.02% -> 0.022993854 | I32: Disc Val | J32: =K25*(1+J31)^(-J30) -> 0.98044318 | K32: =L25*(1+K31)^(-K30) -> 0.96863761 | L32: =M25*(1+L31)^(-L30) -> 96.510669
A33: 2.5 | B33: =G10 -> 0.02431732 | C33: =B33+0.02% -> 0.02451732
A34: 3.25 | B34: =G11 -> 0.025604088 | C34: =B34+0.02% -> 0.025804088 | J34: Discounted price | K34: =SUM(J26,J32:L32) -> 99.456729
J35: Market Price | K35: =K34 -> 99.456729
A36: diminuzione del market price
A39: diminuzione della curva dei tassi | I39: Dates | J39: 45931 | K39: 46113 | L39: 46296 | M39: 46478
A40: t | B40: i(0,t) | C40: i(0,t) - 0.02% | I40: Time to mat | J40: 0.5 | K40: 1 | L40: 1.5 | M40: 2
A41: 0.083333333 | B41: =G4 -> 0.00015121238 | C41: =B41-0.02% -> -4.8787616e-05 | I41: Payments | J41: 1 | K41: 1 | L41: 1 | M41: 101
A42: 0.41666667 | B42: =G5 -> 0.0042125271 | C42: =B42-0.02% -> 0.0040125271 | I42: Disc Val | J42: =J41*(1+C43)^(-J40) -> 0.99717814
A43: 0.5 | B43: =G6 -> 0.0058676968 | C43: =B43-0.02% -> 0.0056676968
A44: 0.75 | B44: =G7 -> 0.013036279 | C44: =B44-0.02% -> 0.012836279 | I44: i(0,0.92) | J44: =E8 -> 0.91666667 | K44: =C45 -> 0.01929301
A45: 0.91666667 | B45: =G8 -> 0.01949301 | C45: =B45-0.02% -> 0.01929301 | I45: i(0,2.5) | J45: =E10 -> 2.5 | K45: =C49 -> 0.02411732
A46: 1 | B46: =J11 -> 0.019746921 | C46: =J47 -> 0.019546921 | I46: T | J46: 1 | K46: 1.5 | L46: 2
A47: 1.5 | B47: =K11 -> 0.021270387 | C47: =K47 -> 0.021070387 | I47: i(0,T) | J47: =(($J$29-J46)*$K$44+(J46-$J$28)*$K$45)/($J$29-$J$28) -> 0.019546921 | K47: =(($J$29-K46)*$K$44+(K46-$J$28)*$K$45)/($J$29-$J$28) -> 0.021070387 | L47: =(($J$29-L46)*$K$44+(L46-$J$28)*$K$45)/($J$29-$J$28) -> 0.022593854
A48: 2 | B48: =G9 -> 0.022793854 | C48: =B48-0.02% -> 0.022593854 | I48: Disc Val | J48: =K41*(1+J47)^(-J46) -> 0.98082784 | K48: =L41*(1+K47)^(-K46) -> 0.96920686 | L48: =M41*(1+L47)^(-L46) -> 96.586186
...

Sheet punto 4
A1: Today | B1: 45383 | E1: ZCB | I1: Coupon bond with maturity 1 giu 29
A3: Coupon | B3: Maturity | C3: Price | E3: Time to maturity (T) | F3: p(0,T) | G3: i(0,T) | I3: Dates | K3: 45809 | L3: 45992 | M3: 46174 | N3: 46357 | O3: 46539 | P3: 46722 | Q3: 46905 | R3: 47088 | S3: 47270
A4: no | B4: 45778 | C4: 99.99874 | E4: 0.083333333 | F4: 0.9999874 | G4: 0.00015121238 | I4: Time to mat (T) | K4: =2/12 -> 0.16666667 | L4: =K4+0.5 -> 0.66666667 | M4: =L4+0.5 -> 1.1666667 | N4: =M4+0.5 -> 1.6666667 | O4: =N4+0.5 -> 2.1666667 | P4: =O4+0.5 -> 2.6666667 | Q4: =P4+0.5 -> 3.1666667 | R4: =Q4+0.5 -> 3.6666667 | S4: =R4+0.5 -> 4.1666667
A5: no | B5: 45901 | C5: 99.825 | E5: 0.41666667 | F5: 0.99825 | G5: 0.0042125271 | I5: Payments | K5: 1 | L5: 1 | M5: 1 | N5: 1 | O5: 1 | P5: 1 | Q5: 1 | R5: 1 | S5: 101
A6: no | B6: 45931 | C6: 99.7079 | E6: 0.5 | F6: 0.997079 | G6: 0.0058676968 | I6: i(0,T) | K6: =((K4-$J$9)*$K$10+($J$10-K4)*$K$9)/($J$10-$J$9) -> 0.0011665411 | L6: =((L4-$J$11)*$K$12+($J$12-L4)*$K$11)/($J$12-$J$11) -> 0.010646752 | M6: =((M4-$J$13)*$K$14+($J$14-M4)*$K$13)/($J$14-$J$13) -> 0.020254743 | N6: =((N4-$J$13)*$K$14+($J$14-N4)*$K$13)/($J$14-$J$13) -> 0.021778209 | O6: =((O4-$J$13)*$K$14+($J$14-O4)*$K$13)/($J$14-$J$13) -> 0.023301676 | P6: =((P4-$J$14)*$K$15+($J$15-P4)*$K$14)/($J$15-$J$14) -> 0.024603269 | Q6: =((Q4-$J$14)*$K$15+($J$15-Q4)*$K$14)/($J$15-$J$14) -> 0.025461114 | R6: =((R4-$J$14)*$K$15+($J$15-R4)*$K$14)/($J$15-$J$14) -> 0.026318959 | S6: =((S4-$J$14)*$K$15+($J$15-S4)*$K$14)/($J$15-$J$14) -> 0.027176805
A7: no | B7: 46023 | C7: 99.0333 | E7: 0.75 | F7: 0.990333 | G7: 0.013036279 | I7: DiscVal | K7: =K5*(1+K6)^(-K4) -> 0.99980571 | L7: =L5*(1+L6)^(-L4) -> 0.99296455 | M7: =M5*(1+M6)^(-M4) -> 0.97687713 | N7: =N5*(1+N6)^(-N4) -> 0.9647296 | O7: =O5*(1+O6)^(-O4) -> 0.9513172 | P7: =P5*(1+P6)^(-P4) -> 0.93724119 | Q7: =Q5*(1+Q6)^(-Q4) -> 0.92346948 | R7: =R5*(1+R6)^(-R4) -> 0.90914128 | S7: =S5*(1+S6)^(-S4) -> 90.323278
A8: no | B8: 46082 | C8: 98.2459 | E8: 0.91666667 | F8: 0.982459 | G8: 0.01949301
A9: 0.02 | B9: 46478 | C9: 99.495053 | E9: 2 | G9: 0.022793854 | I9: i(0,0.08) | J9: =E4 -> 0.083333333 | K9: =G4 -> 0.00015121238
A10: 0.027 | B10: 46661 | C10: 100.71 | E10: 2.5 | G10: 0.02431732 | I10: i(0,0.42) | J10: =E5 -> 0.41666667 | K10: =G5 -> 0.0042125271
A11: 0.005 | B11: 46935 | C11: 93.67 | E11: 3.25 | G11: 0.025604088 | I11: i(0,0.50) | J11: =E6 -> 0.5 | K11: =G6 -> 0.0058676968 | O11: Discounted Price | Q11: =SUM(K7:S7) -> 97.978824
A12: 0.02 | B12: 47270 | C12: =Q12 -> 97.312158 | E12: =50/12 -> 4.1666667 | G12: =S6 -> 0.027176805 | I12: i(0,0.75) | J12: =E7 -> 0.75 | K12: =G7 -> 0.013036279 | O12: Market Price | Q12: =Q11-Q13 -> 97.312158
I13: i(0,0.92) | J13: =E8 -> 0.91666667 | K13: =G8 -> 0.01949301 | O13: Rateo | Q13: =2*4/12 -> 0.66666667
I14: i(0,2.50) | J14: =E10 -> 2.5 | K14: =G10 -> 0.02431732
I15: i(0,3.25) | J15: =E11 -> 3.25 | K15: =G11 -> 0.025604088
B16: curva dei tassi | C16: market price | D16: variazione
B17: i(0,t) | C17: =C12 -> 97.312158 | D17: -
B18: i(0,t) + 0,02% | C18: =Q34 -> 97.236104 | D18: =C18-C17 -> -0.076053196
B19: i(0,t) - 0,02% | C19: =Q56 -> 97.388287 | D19: =C19-C17 -> 0.076128876
I23: Coupon bond with maturity 1 giu 29
A24: aumento della curva dei tassi
A25: t | B25: i(0,t) | C25: i(0,t) + 0.02% | I25: Dates | K25: 45809 | L25: 45992 | M25: 46174 | N25: 46357 | O25: 46539 | P25: 46722 | Q25: 46905 | R25: 47088 | S25: 47270
A26: =E4 -> 0.083333333 | B26: =G4 -> 0.00015121238 | C26: =B26+0.02% -> 0.00035121238 | I26: Time to mat (T) | K26: =2/12 -> 0.16666667 | L26: =K26+0.5 -> 0.66666667 | M26: =L26+0.5 -> 1.1666667 | N26: =M26+0.5 -> 1.6666667 | O26: =N26+0.5 -> 2.1666667 | P26: =O26+0.5 -> 2.6666667 | Q26: =P26+0.5 -> 3.1666667 | R26: =Q26+0.5 -> 3.6666667 | S26: =R26+0.5 -> 4.1666667
A27: =K4 -> 0.16666667 | B27: =K6 -> 0.0011665411 | C27: =K28 -> 0.0013665411 | D27: =C27-B27 -> 0.0002 | I27: Payments | K27: 1 | L27: 1 | M27: 1 | N27: 1 | O27: 1 | P27: 1 | Q27: 1 | R27: 1 | S27: 101
A28: =E5 -> 0.41666667 | B28: =G5 -> 0.0042125271 | C28: =B28+0.02% -> 0.0044125271 | I28: i(0,T) | K28: =((K26-$J$31)*$K$32+($J$32-K26)*$K$31)/($J$32-$J$31) -> 0.0013665411 | L28: =((L26-$J$33)*$K$34+($J$34-L26)*$K$33)/($J$34-$J$33) -> 0.010846752 | M28: =((M26-$J$35)*$K$36+($J$36-M26)*$K$35)/($J$36-$J$35) -> 0.020454743 | N28: =((N26-$J$35)*$K$36+($J$36-N26)*$K$35)/($J$36-$J$35) -> 0.021978209 | O28: =((O26-$J$35)*$K$36+($J$36-O26)*$K$35)/($J$36-$J$35) -> 0.023501676 | P28: =((P26-$J$36)*$K$37+($J$37-P26)*$K$36)/($J$37-$J$36) -> 0.024803269 | Q28: =((Q26-$J$36)*$K$37+($J$37-Q26)*$K$36)/($J$37-$J$36) -> 0.025661114 | R28: =((R26-$J$36)*$K$37+($J$37-R26)*$K$36)/($J$37-$J$36) -> 0.026518959 | S28: =((S26-$J$36)*$K$37+($J$37-S26)*$K$36)/($J$37-$J$36) -> 0.027376805
A29: =E6 -> 0.5 | B29: =G6 -> 0.0058676968 | C29: =B29+0.02% -> 0.0060676968 | I29: DiscVal | K29: =K27*(1+K28)^(-K26) -> 0.99977242 | L29: =L27*(1+L28)^(-L26) -> 0.99283357 | M29: =M27*(1+M28)^(-M26) -> 0.97665376 | N29: =N27*(1+N28)^(-N26) -> 0.96441496 | O29: =O27*(1+O28)^(-O26) -> 0.95091447 | P29: =P27*(1+P28)^(-P26) -> 0.93675351 | Q29: =Q27*(1+Q28)^(-Q26) -> 0.92289936 | R29: =R27*(1+R28)^(-R26) -> 0.90849197 | S29: =S27*(1+S28)^(-S26) -> 90.250037
A30: =L26 -> 0.66666667 | B30: =L6 -> 0.010646752 | C30: =L28 -> 0.010846752 | D30: =C30-B30 -> 0.0002
A31: =E7 -> 0.75 | B31: =G7 -> 0.013036279 | C31: =B31+0.02% -> 0.013236279 | I31: i(0,0.08) | J31: =A26 -> 0.083333333 | K31: =C26 -> 0.00035121238
A32: =E8 -> 0.91666667 | B32: =G8 -> 0.01949301 | C32: =B32+0.02% -> 0.01969301 | I32: i(0,0.42) | J32: =A28 -> 0.41666667 | K32: =C28 -> 0.0044125271
A33: =M26 -> 1.1666667 | B33: =M6 -> 0.020254743 | C33: =M28 -> 0.020454743 | D33: =C33-B33 -> 0.0002 | I33: i(0,0.50) | J33: =A29 -> 0.5 | K33: =C29 -> 0.0060676968 | O33: Discounted Price | Q33: =SUM(K29:S29) -> 97.902771
A34: =N26 -> 1.6666667 | B34: =N6 -> 0.021778209 | C34: =N28 -> 0.021978209 | D34: =C34-B34 -> 0.0002 | I34: i(0,0.75) | J34: =A31 -> 0.75 | K34: =C31 -> 0.013236279 | O34: Market Price | Q34: =Q33-Q35 -> 97.236104
A35: =E9 -> 2 | B35: =G9 -> 0.022793854 | C35: =B35+0.02% -> 0.022993854 | I35: i(0,0.92) | J35: =A32 -> 0.91666667 | K35: =C32 -> 0.01969301 | O35: Rateo | Q35: =2*4/12 -> 0.66666667
A36: =O26 -> 2.1666667 | B36: =O6 -> 0.023301676 | C36: =O28 -> 0.023501676 | D36: =C36-B36 -> 0.0002 | I36: i(0,2.50) | J36: =A37 -> 2.5 | K36: =C37 -> 0.02451732
A37: =E10 -> 2.5 | B37: =G10 -> 0.02431732 | C37: =B37+0.02% -> 0.02451732 | I37: i(0,3.25) | J37: =A40 -> 3.25 | K37: =C40 -> 0.025804088
A38: =P26 -> 2.6666667 | B38: =P6 -> 0.024603269 | C38: =P28 -> 0.024803269 | D38: =C38-B38 -> 0.0002
A39: =Q26 -> 3.1666667 | B39: =Q6 -> 0.025461114 | C39: =Q28 -> 0.025661114 | D39: =C39-B39 -> 0.0002
A40: =E11 -> 3.25 | B40: =G11 -> 0.025604088 | C40: =B40+0.02% -> 0.025804088
A41: =R26 -> 3.6666667 | B41: =R6 -> 0.026318959 | C41: =R28 -> 0.026518959 | D41: =C41-B41 -> 0.0002
A42: =S26 -> 4.1666667 | B42: =S6 -> 0.027176805 | C42: =S28 -> 0.027376805 | D42: =C42-B42 -> 0.0002
I45: Coupon bond with maturity 1 giu 29
A46: aumento della curva dei tassi
...

Sheet punto 5-6
A1: PORTAFOGLIO
A2: cedola | B2: date | C2: price | D2: t | E2: i(0,t) | F2: quota parte
A3: 0.02 | B3: 46478 | C3: ='punto 1-2-3'!C9 -> 99.495053 | D3: 2 | E3: ='punto 1-2-3'!G9 -> 0.022793854 | F3: =2/5 -> 0.4
A4: 0.02 | B4: 47270 | C4: ='punto 4'!C17 -> 97.312158 | D4: 4.1666667 | E4: ='punto 4'!G12 -> 0.027176805 | F4: =3/5 -> 0.6
A7: t | B7: t^2 | C7: t+1 | D7: t+2 | E7: i(0,t) | F7: 1+i(0,t) | G7: (1+i(0,t))^(-t) | H7: (1+i(0,t))^(-(t+2)) | J7: x1(0,t) | K7: m1 | L7: x2(0,t) | M7: m2 | N7: x_tot (0,t)
A8: =2/12 -> 0.16666667 | B8: =A8^2 -> 0.027777778 | C8: =A8+1 -> 1.1666667 | D8: =A8+2 -> 2.1666667 | E8: ='punto 4'!B27 -> 0.0011665411 | F8: =1+E8 -> 1.0011665 | G8: =F8^(-A8) -> 0.99980571 | H8: =F8^(-D8) -> 0.99747716 | J8: 0 | K8: =J8*G8/$D$24 -> 0 | L8: 1 | M8: =L8*G8/$D$25 -> 0.010274212 | N8: =J8*$E$24+L8*$E$25 -> 0.6
A9: =0.5 -> 0.5 | B9: =A9^2 -> 0.25 | C9: =A9+1 -> 1.5 | D9: =A9+2 -> 2.5 | E9: ='punto 1-2-3'!B27 -> 0.0058676968 | F9: =1+E9 -> 1.0058677 | G9: =F9^(-A9) -> 0.997079 | H9: =F9^(-D9) -> 0.98548007 | J9: 1 | K9: =J9*G9/$D$24 -> 0.010021393 | L9: 0 | M9: =L9*G9/$D$25 -> 0 | N9: =J9*$E$24+L9*$E$25 -> 0.4
A10: =8/12 -> 0.66666667 | B10: =A10^2 -> 0.44444444 | C10: =A10+1 -> 1.6666667 | D10: =A10+2 -> 2.6666667 | E10: ='punto 4'!B30 -> 0.010646752 | F10: =1+E10 -> 1.0106468 | G10: =F10^(-A10) -> 0.99296455 | H10: =F10^(-D10) -> 0.97215379 | J10: 0 | K10: =J10*G10/$D$24 -> 0 | L10: 1 | M10: =L10*G10/$D$25 -> 0.010203911 | N10: =J10*$E$24+L10*$E$25 -> 0.6
A11: =1 -> 1 | B11: =A11^2 -> 1 | C11: =A11+1 -> 2 | D11: =A11+2 -> 3 | E11: ='punto 1-2-3'!B30 -> 0.019746921 | F11: =1+E11 -> 1.0197469 | G11: =F11^(-A11) -> 0.98063547 | H11: =F11^(-D11) -> 0.9430241 | J11: 1 | K11: =J11*G11/$D$24 -> 0.0098561229 | L11: 0 | M11: =L11*G11/$D$25 -> 0 | N11: =J11*$E$24+L11*$E$25 -> 0.4
A12: =14/12 -> 1.1666667 | B12: =A12^2 -> 1.3611111 | C12: =A12+1 -> 2.1666667 | D12: =A12+2 -> 3.1666667 | E12: ='punto 4'!B33 -> 0.020254743 | F12: =1+E12 -> 1.0202547 | G12: =F12^(-A12) -> 0.97687713 | H12: =F12^(-D12) -> 0.93847497 | J12: 0 | K12: =J12*G12/$D$24 -> 0 | L12: 1 | M12: =L12*G12/$D$25 -> 0.010038593 | N12: =J12*$E$24+L12*$E$25 -> 0.6
A13: =1.5 -> 1.5 | B13: =A13^2 -> 2.25 | C13: =A13+1 -> 2.5 | D13: =A13+2 -> 3.5 | E13: ='punto 1-2-3'!B31 -> 0.021270387 | F13: =1+E13 -> 1.0212704 | G13: =F13^(-A13) -> 0.96892217 | H13: =F13^(-D13) -> 0.92898224 | J13: 1 | K13: =J13*G13/$D$24 -> 0.0097383954 | L13: 0 | M13: =L13*G13/$D$25 -> 0 | N13: =J13*$E$24+L13*$E$25 -> 0.4
A14: =20/12 -> 1.6666667 | B14: =A14^2 -> 2.7777778 | C14: =A14+1 -> 2.6666667 | D14: =A14+2 -> 3.6666667 | E14: ='punto 4'!B34 -> 0.021778209 | F14: =1+E14 -> 1.0217782 | G14: =F14^(-A14) -> 0.9647296 | H14: =F14^(-D14) -> 0.92404332 | J14: 0 | K14: =J14*G14/$D$24 -> 0 | L14: 1 | M14: =L14*G14/$D$25 -> 0.0099137623 | N14: =J14*$E$24+L14*$E$25 -> 0.6
A15: =2 -> 2 | B15: =A15^2 -> 4 | C15: =A15+1 -> 3 | D15: =A15+2 -> 4 | E15: ='punto 1-2-3'!B32 -> 0.022793854 | F15: =1+E15 -> 1.0227939 | G15: =F15^(-A15) -> 0.95592491 | H15: =F15^(-D15) -> 0.91379244 | J15: 101 | K15: =J15*G15/$D$24 -> 0.97038409 | L15: 0 | M15: =L15*G15/$D$25 -> 0 | N15: =J15*$E$24+L15*$E$25 -> 40.4
A16: =26/12 -> 2.1666667 | B16: =A16^2 -> 4.6944444 | C16: =A16+1 -> 3.1666667 | D16: =A16+2 -> 4.1666667 | E16: ='punto 4'!B36 -> 0.023301676 | F16: =1+E16 -> 1.0233017 | G16: =F16^(-A16) -> 0.9513172 | H16: =F16^(-D16) -> 0.90848545 | J16: 0 | K16: =J16*G16/$D$24 -> 0 | L16: 1 | M16: =L16*G16/$D$25 -> 0.0097759337 | N16: =J16*$E$24+L16*$E$25 -> 0.6
A17: =A16+0.5 -> 2.6666667 | B17: =A17^2 -> 7.1111111 | C17: =A17+1 -> 3.6666667 | D17: =A17+2 -> 4.6666667 | E17: ='punto 4'!B38 -> 0.024603269 | F17: =1+E17 -> 1.0246033 | G17: =F17^(-A17) -> 0.93724119 | H17: =F17^(-D17) -> 0.89277063 | J17: 0 | K17: =J17*G17/$D$24 -> 0 | L17: 1 | M17: =L17*G17/$D$25 -> 0.0096312857 | N17: =J17*$E$24+L17*$E$25 -> 0.6
A18: =A17+0.5 -> 3.1666667 | B18: =A18^2 -> 10.027778 | C18: =A18+1 -> 4.1666667 | D18: =A18+2 -> 5.1666667 | E18: ='punto 4'!B39 -> 0.025461114 | F18: =1+E18 -> 1.0254611 | G18: =F18^(-A18) -> 0.92346948 | H18: =F18^(-D18) -> 0.87818123 | J18: 0 | K18: =J18*G18/$D$24 -> 0 | L18: 1 | M18: =L18*G18/$D$25 -> 0.0094897647 | N18: =J18*$E$24+L18*$E$25 -> 0.6
A19: =A18+0.5 -> 3.6666667 | B19: =A19^2 -> 13.444444 | C19: =A19+1 -> 4.6666667 | D19: =A19+2 -> 5.6666667 | E19: ='punto 4'!B41 -> 0.026318959 | F19: =1+E19 -> 1.026319 | G19: =F19^(-A19) -> 0.90914128 | H19: =F19^(-D19) -> 0.86311104 | J19: 0 | K19: =J19*G19/$D$24 -> 0 | L19: 1 | M19: =L19*G19/$D$25 -> 0.0093425251 | N19: =J19*$E$24+L19*$E$25 -> 0.6
A20: =A19+0.5 -> 4.1666667 | B20: =A20^2 -> 17.361111 | C20: =A20+1 -> 5.1666667 | D20: =A20+2 -> 6.1666667 | E20: ='punto 4'!B42 -> 0.027176805 | F20: =1+E20 -> 1.0271768 | G20: =F20^(-A20) -> 0.89428988 | H20: =F20^(-D20) -> 0.84759407 | J20: 0 | K20: =J20*G20/$D$24 -> 0 | L20: 101 | M20: =L20*G20/$D$25 -> 0.92818082 | N20: =J20*$E$24+L20*$E$25 -> 60.6
C23: k | D23: p(0,x_k) | E23: alpha_k | F23: DU(0,x_k) | G23: C(0,x_k) | J23: DURATION | M23: =(D24*E24*F24+D25*E25*F25)/(D24*E24+D25*E25) -> 3.1863895
C24: 1 | D24: =C3 -> 99.495053 | E24: =2/5 -> 0.4 | F24: {=SUM(A8:A20*K8:K20)} -> 1.9702426 | G24: {=SUM(A8:A20*C8:C20*J8:J20*H8:H20)/SUM(J8:J20*G8:G20)} -> 5.6270844 | J24: CONVEXITY | M24: =(D24*E24*G24+D25*E25*G25)/(D24*E24+D25*E25) -> 13.764001
C25: 2 | D25: =C4 -> 97.312158 | E25: =3/5 -> 0.6 | F25: {=SUM(A8:A20*M8:M20)} -> 4.0153411 | G25: {=SUM(A8:A20*C8:C20*H8:H20*L8:L20)/SUM(L8:L20*G8:G20)} -> 19.310297
A33: IMMUNIZZAZIONE
A35: L | B35: 4000 | E35: k | F35: p(0,x_k) | G35: DU(0,x_k) | I35: =F36 -> 99.495053 | J35: w1 + | K35: =F37 -> 97.312158 | L35: w2 = | M35: =B38 -> 3712.494
A36: DU(0,L) | B36: 3 | E36: 1 | F36: =D24 -> 99.495053 | G36: =F24 -> 1.9702426 | I36: =F36*G36 -> 196.02939 | J36: w1 + | K36: =F37*G37 -> 390.74151 | L36: w2 = | M36: =B36*M35 -> 11137.482
A37: i(0,3) | B37: =((A41-B36)*B40+(B36-A40)*B41)/(A41-A40) -> 0.025175166 | C37: interpol | E37: 2 | F37: =D25 -> 97.312158 | G37: =F25 -> 4.0153411
A38: p(0,L) | B38: =B35*(1+B37)^(-B36) -> 3712.494 | I38: D = | J38: =I35 -> 99.495053 | K38: =K35 -> 97.312158 | L38: = | M38: =MDETERM(J38:K39) -> 19800.804
J39: =I36 -> 196.02939 | K39: =K36 -> 390.74151
A40: 2.5 | B40: =lezione!G9 -> 0.02431732 | F40: w_k | G40: =M41/M38 -> 18.525162
A41: 3.25 | B41: =lezione!G10 -> 0.025604088 | G41: =M44/M38 -> 19.209645 | I41: D1 = | J41: =M35 -> 3712.494 | K41: =K35 -> 97.312158 | L41: = | M41: =MDETERM(J41:K42) -> 366813.11
J42: =M36 -> 11137.482 | K42: =K36 -> 390.74151
E43: equilibrio flussi | G43: =G40*F36+G41*F37-B38 -> 0
E44: duration matching | G44: =G40*F36*F24+G41*F37*F25-B36*B38 -> 0 | I44: D2 = | J44: =I35 -> 99.495053 | K44: =M35 -> 3712.494 | L44: = | M44: =MDETERM(J44:K45) -> 380366.42
J45: =I36 -> 196.02939 | K45: =M36 -> 11137.482
