Workbook
Name DJIA: Venerdì!$W$12:$W$115
Name DJIA_9: Venerdì!$W$3:$W$11
Name e: Venerdì!$W$129:$W$133
Name HSI: Venerdì!$X$12:$X$115
Name HSI_9: Venerdì!$X$3:$X$11
Name IXIC: Venerdì!$AA$12:$AA$115
Name IXIC_9: Venerdì!$AA$3:$AA$11
Name N225E: Venerdì!$Y$12:$Y$115
Name N225E_9: Venerdì!$Y$3:$Y$11
Name STOXX: Venerdì!$Z$12:$Z$115
Name STOXX_9: Venerdì!$Z$3:$Z$11
Name V: Venerdì!$W$123:$AA$127
Name V_9: Ricalcolo!#REF!
Name V_9: Consegna!$K$43:$O$47

Sheet Stock aggiornato
B2: LEGENDA | D2: LUNEDI | E2: VENERDI
D3: LUNEDI E VENERDI
P5: RENDIMENTI SETTIMANALI | Q5: DJIA | R5: HSI | S5: N225E | T5: STOXX | U5: IXIC
A6: Date | B6: DJIA | D6: Date | E6: HSI | G6: Date | H6: N225E | J6: Date | K6: STOXX | M6: Date | N6: IXIC
A7: 45807 | B7: 42215.73 | D7: 45807 | E7: 2969.99 | G7: 45807 | H7: 263.3 | J7: 45807 | K7: 626.24 | M7: 45807 | N7: 19175.87 | Q7: =(B7-B8)/B8 -> 0.014726317 | R7: =(E7-E8)/E8 -> -0.014356592 | S7: =(H7-H8)/H8 -> 0.0099731492 | T7: =(K7-K8)/K8 -> 0.01089606 | U7: =(N7-N8)/N8 -> 0.02341117
A8: 45800 | B8: 41603.07 | D8: 45800 | E8: 3013.25 | G8: 45800 | H8: 260.7 | J8: 45800 | K8: 619.49 | M8: 45800 | N8: 18737.21 | Q8: =(B8-B9)/B9 -> -0.024655408 | R8: =(E8-E9)/E9 -> 0.0085618559 | S8: =(H8-H9)/H9 -> 0.0055542698 | T8: =(K8-K9)/K9 -> 0.010356525 | U8: =(N8-N9)/N9 -> -0.02466751
A9: 45793 | B9: 42654.74 | D9: 45793 | E9: 2987.67 | G9: 45793 | H9: 259.26 | J9: 45793 | K9: 613.14 | M9: 45793 | N9: 19211.1 | Q9: =(B9-B10)/B10 -> 0.034069845 | R9: =(E9-E10)/E10 -> 0.01627305 | S9: =(H9-H10)/H10 -> 0.0047279492 | T9: =(K9-K10)/K10 -> 0.013387545 | U9: =(N9-N10)/N10 -> 0.071514626
A10: 45786 | B10: 41249.38 | D10: 45786 | E10: 2939.83 | G10: 45786 | H10: 258.04 | J10: 45786 | K10: 605.04 | M10: 45786 | N10: 17928.92 | Q10: =(B10-B11)/B11 -> -0.0016470047 | R10: =(E10-E11)/E11 -> 0.01239742 | S10: =(H10-H11)/H11 -> 0.015385826 | T10: =(K10-K11)/K11 -> -0.0014193761 | U10: =(N10-N11)/N11 -> -0.0027150258
A11: 45779 | B11: 41317.43 | D11: 45779 | E11: 2903.83 | G11: 45779 | H11: 254.13 | J11: 45779 | K11: 605.9 | M11: 45779 | N11: 17977.73 | Q11: =(B11-B12)/B12 -> 0.030013088 | R11: =(E11-E12)/E12 -> 0.024734097 | S11: =(H11-H12)/H12 -> 0.022532491 | T11: =(K11-K12)/K12 -> 0.024448803 | U11: =(N11-N12)/N12 -> 0.034216882
A12: 45772 | B12: 40113.5 | D12: 45772 | E12: 2833.74 | G12: 45772 | H12: 248.53 | J12: 45772 | K12: 591.44 | M12: 45772 | N12: 17382.94 | Q12: =(B12-B13)/B13 -> 0.024813865 | R12: =(E12-E13)/E13 -> 0.02803223 | S12: =(H12-H13)/H13 -> 0.017356421 | T12: =(K12-K13)/K13 -> 0.025274763 | U12: =(N12-N13)/N13 -> 0.067325292
A13: 45765 | B13: 39142.23 | D13: 45765 | E13: 2756.47 | G13: 45765 | H13: 244.29 | J13: 45765 | K13: 576.86 | M13: 45765 | N13: 16286.45 | Q13: =(B13-B14)/B14 -> -0.026620439 | R13: =(E13-E14)/E14 -> 0.021864771 | S13: =(H13-H14)/H14 -> 0.043840533 | T13: =(K13-K14)/K14 -> 0.043127611 | U13: =(N13-N14)/N14 -> -0.026189784
A14: 45758 | B14: 40212.71 | D14: 45758 | E14: 2697.49 | G14: 45758 | H14: 234.03 | J14: 45758 | K14: 553.01 | M14: 45758 | N14: 16724.46 | Q14: =(B14-B15)/B15 -> 0.049533001 | R14: =(E14-E15)/E15 -> -0.082230418 | S14: =(H14-H15)/H15 -> 0.01769873 | T14: =(K14-K15)/K15 -> 0.017067294 | U14: =(N14-N15)/N15 -> 0.072920536
A15: 45751 | B15: 38314.86 | D15: 45751 | E15: 2939.18 | G15: 45751 | H15: 229.96 | J15: 45751 | K15: 543.73 | M15: 45751 | N15: 15587.79 | Q15: =(B15-B16)/B16 -> -0.078613117 | R15: =(E15-E16)/E16 -> -0.024171062 | S15: =(H15-H16)/H16 -> -0.071928843 | T15: =(K15-K16)/K16 -> -0.073602836 | U15: =(N15-N16)/N16 -> -0.10016747
A16: 45744 | B16: 41583.9 | D16: 45744 | E16: 3011.9828 | G16: 45744 | H16: 247.78272 | J16: 45744 | K16: 586.92969 | M16: 45744 | N16: 17322.99 | P16: 1 | Q16: =(B16-B20)/B20 -> -0.023469693 | R16: =(E16-E20)/E20 -> -0.020489089 | S16: =(H16-H20)/H20 -> -0.0071821868 | T16: =(K16-K20)/K20 -> -0.0099724781 | U16: =(N16-N20)/N20 -> -0.047590432
A17: 45743 | B17: 42299.7 | D17: 45743 | E17: 3032.4871 | G17: 45743 | H17: 250.24806 | J17: 45743 | K17: 590.06956 | M17: 45743 | N17: 17804.033 | P17: 2 | Q17: =(B21-B25)/B25 -> 0.0034347128 | R17: =(E21-E25)/E25 -> -0.019358863 | S17: =(H21-H24)/H24 -> 0.0068269957 | T17: =(K21-K25)/K25 -> -0.012080021 | U17: =(N21-N25)/N25 -> -0.0013820801
A18: 45742 | B18: 42454.786 | D18: 45742 | E18: 3019.9354 | G18: 45742 | H18: 252.53878 | J18: 45742 | K18: 589.99419 | M18: 45742 | N18: 17899.015 | P18: 3 | Q18: =(B26-B30)/B30 -> -0.010105054 | R18: =(E26-E30)/E30 -> 0.0068504167 | S18: =(H25-H29)/H29 -> -0.0084864221 | T18: =(K26-K30)/K30 -> 0.0050762424 | U18: =(N26-N30)/N30 -> 0.016359042
A19: 45741 | B19: 42587.497 | D19: 45741 | E19: 3002.5917 | G19: 45741 | H19: 252.03829 | J19: 45741 | K19: 596.29869 | M19: 45741 | N19: 18271.855 | P19: 4 | Q19: =(B31-B35)/B35 -> -0.0090186775 | R19: =(E31-E35)/E35 -> 0.054155852 | S19: =(H30-H34)/H34 -> -0.014079352 | T19: =(K31-K35)/K35 -> 0.015054057 | U19: =(N31-N35)/N35 -> -0.0083906484
A20: 45740 | B20: 42583.317 | D20: 45740 | E20: 3074.9865 | G20: 45740 | H20: 249.57522 | J20: 45740 | K20: 592.84179 | M20: 45740 | N20: 18188.593 | P20: 5 | Q20: =(B36-B40)/B40 -> 0.0087363595 | R20: =(E36-E40)/E40 -> -0.01757882 | S20: =(H35-H38)/H38 -> -0.038498617 | T20: =(K36-K40)/K40 -> -0.0018975893 | U20: =(N36-N40)/N40 -> -0.022795028
A21: 45737 | B21: 41985.349 | D21: 45737 | E21: 3047.5757 | G21: 45737 | H21: 252.34117 | J21: 45737 | K21: 594.41134 | M21: 45737 | N21: 17784.051 | P21: 6 | Q21: =(B41-B44)/B44 -> -0.025323476 | R21: =(E41-E45)/E45 -> 0.039530166 | S21: =(H39-H43)/H43 -> 0.0045111434 | T21: =(K41-K45)/K45 -> -0.0051105076 | U21: =(N41-N44)/N44 -> -0.025809554
A22: 45736 | B22: 41953.324 | D22: 45736 | E22: 3116.068 | G22: 45735 | H22: 253.91364 | J22: 45736 | K22: 600.04123 | M22: 45736 | N22: 17691.626 | P22: 7 | Q22: =(B45-B49)/B49 -> 0.0017015382 | R22: =(E46-E50)/E50 -> 0.051627968 | S22: =(H44-H47)/H47 -> 0.0067234729 | T22: =(K46-K50)/K50 -> 0.030051645 | U22: =(N45-N49)/N49 -> 0.015851614
A23: 45735 | B23: 41964.634 | D23: 45735 | E23: 3187.7617 | G23: 45734 | H23: 253.55366 | J23: 45735 | K23: 605.40688 | M23: 45735 | N23: 17750.79 | P23: 8 | Q23: =(B50-B54)/B54 -> -0.0026678704 | R23: =(E51-E55)/E55 -> 0.045603443 | S23: =(H48-H52)/H52 -> 0.029209778 | T23: =(K51-K55)/K55 -> 0.013093779 | U23: =(N50-N54)/N54 -> 0.0067784295
A24: 45734 | B24: 41581.314 | D24: 45734 | E24: 3184.4834 | G24: 45733 | H24: 250.63012 | J24: 45734 | K24: 606.56796 | M24: 45734 | N24: 17504.117 | P24: 9 | Q24: =(B55-B59)/B59 -> -0.0037777404 | R24: =(E56-E57)/E57 -> 0.0011093822 | S24: =(H53-H57)/H57 -> -0.0042781157 | T24: =(K56-K60)/K60 -> 0.0060592133 | U24: =(N55-N59)/N59 -> 0.014766283
A25: 45733 | B25: 41841.635 | D25: 45733 | E25: 3107.7379 | G25: 45730 | H25: 249.31436 | J25: 45733 | K25: 601.67964 | M25: 45733 | N25: 17808.664 | P25: 10 | Q25: =(B60-B63)/B63 -> 0.0090501648 | R25: =(E58-E62)/E62 -> 0.0061786527 | S25: =(H58-H62)/H62 -> 0.023896594 | T25: =(K61-K65)/K65 -> 0.019511192 | U25: =(N60-N63)/N63 -> 0.0099976823
A26: 45730 | B26: 41488.189 | D26: 45730 | E26: 3082.5417 | G26: 45729 | H26: 248.90082 | J26: 45730 | K26: 594.64752 | M26: 45730 | N26: 17754.086 | P26: 11 | Q26: =(B64-B68)/B68 -> 0.028151147 | R26: =(E63-E67)/E67 -> 0.037600043 | S26: =(H63-H66)/H66 -> 0.010020654 | T26: =(K66-K70)/K70 -> 0.032076722 | U26: =(N64-N68)/N68 -> 0.028399733
A27: 45729 | B27: 40813.569 | D27: 45729 | E27: 3018.9856 | G27: 45728 | H27: 248.35811 | J27: 45729 | K27: 586.48493 | M27: 45729 | N27: 17303.014 | P27: 12 | Q27: =(B69-B72)/B72 -> -0.017985861 | R27: =(E68-E72)/E72 -> -0.033186097 | S27: =(H67-H71)/H71 -> -0.0035367073 | T27: =(K71-K75)/K75 -> -0.01697599 | U27: =(N69-N72)/N72 -> -0.035406679
A28: 45728 | B28: 41350.929 | D28: 45728 | E28: 3037.7148 | G28: 45727 | H28: 248.98904 | J28: 45728 | K28: 589.20543 | M28: 45728 | N28: 17648.45 | P28: 13 | Q28: =(B73-B76)/B76 -> 0.0037207242 | R28: =(E73-E76)/E76 -> -0.01549893 | S28: 0 | T28: =(K76-K79)/K79 -> -0.0029614053 | U28: =(N73-N76)/N76 -> 0.0069222296
A29: 45727 | B29: 41433.482 | D29: 45727 | E29: 3060.6069 | G29: 45726 | H29: 251.44825 | J29: 45727 | K29: 586.17565 | M29: 45727 | N29: 17436.095 | P29: 14 | Q29: =(B77-B80)/B80 -> 0.0019870254 | R29: =(E77-E79)/E79 -> 0.011481887 | S29: =(H73-H77)/H77 -> 0.024293475 | T29: =(K80-K82)/K82 -> 0.010625235 | U29: =(N77-N80)/N80 -> -0.0021681887
A30: 45726 | B30: 41911.709 | D30: 45726 | E30: 3061.5687 | G30: 45723 | H30: 249.18712 | J30: 45726 | K30: 591.64419 | M30: 45726 | N30: 17468.321 | P30: 15 | Q30: =(B81-B85)/B85 -> -0.020065691 | R30: =(E80-E84)/E84 -> -0.0039062647 | S30: =(H78-H82)/H82 -> -0.033321979 | T30: =(K83-K87)/K87 -> -0.033946092 | U30: =(N81-N85)/N85 -> -0.029805554
A31: 45723 | B31: 42801.716 | D31: 45723 | E31: 3118.5313 | G31: 45722 | H31: 254.84914 | J31: 45723 | K31: 599.38907 | M31: 45723 | N31: 18196.221 | P31: 16 | Q31: =(B86-B90)/B90 -> -0.0129245 | R31: =(E85-E89)/E89 -> -0.021806593 | S31: =(H83-H87)/H87 -> -0.0081579696 | T31: =(K88-K92)/K92 -> -0.01384466 | U31: =(N86-N90)/N90 -> 0.0096284635
A32: 45722 | B32: 42579.076 | D32: 45722 | E32: 3135.6181 | G32: 45721 | H32: 251.33154 | J32: 45722 | K32: 599.42419 | M32: 45722 | N32: 18069.255 | P32: 17 | Q32: =(B91-B95)/B95 -> -0.0031144816 | R32: =(E90-E94)/E94 -> 0.016454436 | S32: =(H88-H92)/H92 -> 0.012035034 | T32: =(K93-K97)/K97 -> 0.020210315 | U32: =(N91-N95)/N95 -> 0.023491405
A33: 45721 | B33: 43006.592 | D33: 45721 | E33: 3036.3043 | G33: 45720 | H33: 249.20681 | J33: 45721 | K33: 600.02374 | M33: 45721 | N33: 18552.734 | P33: 18 | Q33: =(B96-B99)/B99 -> 0.003891217 | R33: =(E95-E99)/E99 -> 0.014287429 | S33: =(H93-H97)/H97 -> 0.014590939 | T33: =(K98-K102)/K102 -> 0.01063129 | U33: =(N96-N99)/N99 -> 0.0085716302
A34: 45720 | B34: 42520.988 | D34: 45720 | E34: 2952.0768 | G34: 45719 | H34: 252.74562 | J34: 45720 | K34: 585.4537 | M34: 45720 | N34: 18285.163 | P34: 19 | Q34: =(B100-B104)/B104 -> 0.020901569 | R34: =(E100-E104)/E104 -> -0.017769941 | S34: =(H98-H102)/H102 -> 0.0010657355 | T34: =(K103-K107)/K107 -> -0.0061630097 | U34: =(N100-N104)/N104 -> 0.011273265
A35: 45719 | B35: 43191.244 | D35: 45719 | E35: 2958.3209 | G35: 45716 | H35: 246.71647 | J35: 45719 | K35: 590.49966 | M35: 45719 | N35: 18350.191 | P35: 20 | Q35: =(B105-B109)/B109 -> -0.019148489 | R35: =(E105-E109)/E109 -> -0.050144372 | S35: =(H103-H107)/H107 -> -0.026512987 | T35: =(K108-K112)/K112 -> -0.028476477 | U35: =(N105-N109)/N109 -> -0.032056044
A36: 45716 | B36: 43840.908 | D36: 45716 | E36: 2949.4003 | G36: 45715 | H36: 255.38164 | J36: 45716 | K36: 578.08188 | M36: 45716 | N36: 18847.279 | P36: 21 | Q36: =(B110-B114)/B114 -> 0.052504174 | R36: =(E110-E114)/E114 -> 0.0075007184 | S36: =(H108-H111)/H111 -> 0.019724752 | T36: =(K113-K117)/K117 -> -0.019611951 | U36: =(N110-N114)/N114 -> 0.060879757
A37: 45715 | B37: 43239.497 | D37: 45715 | E37: 3049.6426 | G37: 45714 | H37: 255.85169 | J37: 45715 | K37: 579.2248 | M37: 45715 | N37: 18544.419 | P37: 22 | Q37: =(B115-B119)/B119 -> -0.0079121785 | R37: =(E115-E119)/E119 -> -0.0052153374 | S37: =(H112-H116)/H116 -> -0.012361835 | T37: =(K118-K122)/K122 -> -0.01729418 | U37: =(N115-N119)/N119 -> -0.017626362
A38: 45714 | B38: 43433.124 | D38: 45714 | E38: 3059.9738 | G38: 45713 | H38: 256.59502 | J38: 45714 | K38: 586.69923 | M38: 45714 | N38: 19075.263 | P38: 23 | Q38: =(B120-B124)/B124 -> -0.01903475 | R38: =(E120-E124)/E124 -> 0.0058163445 | S38: =(H117-H121)/H121 -> -0.036109349 | T38: =(K123-K127)/K127 -> -0.0072256185 | U38: =(N120-N124)/N124 -> -0.0011542068
A39: 45713 | B39: 43621.157 | D39: 45713 | E39: 2963.0704 | G39: 45709 | H39: 259.74238 | J39: 45713 | K39: 582.63246 | M39: 45713 | N39: 19026.386 | P39: 24 | Q39: =(B125-B129)/B129 -> 0.0048922772 | R39: =(E125-E129)/E129 -> -0.014464257 | S39: =(H122-H125)/H125 -> -0.025427742 | T39: =(K128-K132)/K132 -> -0.0035077992 | U39: =(N125-N129)/N129 -> -0.00070973483
A40: 45712 | B40: 43461.215 | D40: 45712 | E40: 3002.1749 | G40: 45708 | H40: 258.49121 | J40: 45712 | K40: 579.18093 | M40: 45712 | N40: 19286.925 | P40: 25 | Q40: =(B130-B134)/B134 -> 0.021681398 | R40: =(E130-E133)/E133 -> -0.080477577 | S40: =(H126-H130)/H130 -> 0.0005278027 | T40: =(K133-K137)/K137 -> 0.001416717 | U40: =(N130-N134)/N134 -> 0.023378445
A41: 45709 | B41: 43428.022 | D41: 45709 | E41: 3021.8058 | G41: 45707 | H41: 258.56348 | J41: 45709 | K41: 579.21377 | M41: 45709 | N41: 19524.005 | P41: 26 | Q41: =(B135-B139)/B139 -> 0.00053388425 | R41: =(E134-E137)/E137 -> 0.076759933 | S41: =(H131-H135)/H135 -> -0.015990118 | T41: =(K138-K142)/K142 -> -0.022355326 | U41: =(N135-N139)/N139 -> -0.0028215141
A42: 45708 | B42: 44176.65 | D42: 45708 | E42: 2903.3062 | G42: 45706 | H42: 258.27294 | J42: 45708 | K42: 578.56108 | M42: 45708 | N42: 19962.362 | P42: 27 | Q42: =(B140-B144)/B144 -> 0.0044712607 | R42: =(E138-E142)/E142 -> 0.13270917 | S42: =(H136-H139)/H139 -> 0.057318227 | T42: =(K143-K147)/K147 -> 0.027469046 | U42: =(N140-N144)/N144 -> 0.0080848902
...

Sheet Stock data
B2: LEGENDA | D2: LUNEDI | E2: VENERDI
D3: LUNEDI E VENERDI
P5: RENDIMENTI SETTIMANALI | Q5: DJIA | R5: HSI | S5: N225E | T5: STOXX | U5: IXIC
A6: Date | B6: DJIA | D6: Date | E6: HSI | G6: Date | H6: N225E | J6: Date | K6: STOXX | M6: Date | N6: IXIC | P6: 1 | Q6: =(B8-B12)/B12 -> -0.023469787 | R6: =(E8-E12)/E12 -> -0.020489089 | S6: =(H8-H12)/H12 -> -0.0071821868 | T6: =(K8-K12)/K12 -> -0.0099724781 | U6: =(N8-N12)/N12 -> -0.047590377
A7: 45747 | B7: 42001.761 | D7: 45747 | E7: 2971.592 | G7: 45747 | H7: 237.52958 | J7: 45747 | K7: 577.54173 | M7: 45747 | N7: 17299.287 | P7: 2 | Q7: =(B13-B17)/B17 -> 0.0034347128 | R7: =(E13-E17)/E17 -> -0.019358863 | S7: =(H13-H16)/H16 -> 0.0068269957 | T7: =(K13-K17)/K17 -> -0.012080021 | U7: =(N13-N17)/N17 -> -0.0013820801
A8: 45744 | B8: 41583.896 | D8: 45744 | E8: 3011.9828 | G8: 45744 | H8: 247.78272 | J8: 45744 | K8: 586.92969 | M8: 45744 | N8: 17322.991 | P8: 3 | Q8: =(B18-B22)/B22 -> -0.010105054 | R8: =(E18-E22)/E22 -> 0.0068504167 | S8: =(H17-H21)/H21 -> -0.0084864221 | T8: =(K18-K22)/K22 -> 0.0050762424 | U8: =(N18-N22)/N22 -> 0.016359042
A9: 45743 | B9: 42299.7 | D9: 45743 | E9: 3032.4871 | G9: 45743 | H9: 250.24806 | J9: 45743 | K9: 590.06956 | M9: 45743 | N9: 17804.033 | P9: 4 | Q9: =(B23-B27)/B27 -> -0.0090186775 | R9: =(E23-E27)/E27 -> 0.054155852 | S9: =(H22-H26)/H26 -> -0.014079352 | T9: =(K23-K27)/K27 -> 0.015054057 | U9: =(N23-N27)/N27 -> -0.0083906484
A10: 45742 | B10: 42454.786 | D10: 45742 | E10: 3019.9354 | G10: 45742 | H10: 252.53878 | J10: 45742 | K10: 589.99419 | M10: 45742 | N10: 17899.015 | P10: 5 | Q10: =(B28-B32)/B32 -> 0.0087363595 | R10: =(E28-E32)/E32 -> -0.01757882 | S10: =(H27-H30)/H30 -> -0.038498617 | T10: =(K28-K32)/K32 -> -0.0018975893 | U10: =(N28-N32)/N32 -> -0.022795028
A11: 45741 | B11: 42587.497 | D11: 45741 | E11: 3002.5917 | G11: 45741 | H11: 252.03829 | J11: 45741 | K11: 596.29869 | M11: 45741 | N11: 18271.855 | P11: 6 | Q11: =(B33-B36)/B36 -> -0.025323476 | R11: =(E33-E37)/E37 -> 0.039530166 | S11: =(H31-H35)/H35 -> 0.0045111434 | T11: =(K33-K37)/K37 -> -0.0051105076 | U11: =(N33-N36)/N36 -> -0.025809554
A12: 45740 | B12: 42583.317 | D12: 45740 | E12: 3074.9865 | G12: 45740 | H12: 249.57522 | J12: 45740 | K12: 592.84179 | M12: 45740 | N12: 18188.593 | P12: 7 | Q12: =(B37-B41)/B41 -> 0.0017015382 | R12: =(E38-E42)/E42 -> 0.051627968 | S12: =(H36-H39)/H39 -> 0.0067234729 | T12: =(K38-K42)/K42 -> 0.030051645 | U12: =(N37-N41)/N41 -> 0.015851614
A13: 45737 | B13: 41985.349 | D13: 45737 | E13: 3047.5757 | G13: 45737 | H13: 252.34117 | J13: 45737 | K13: 594.41134 | M13: 45737 | N13: 17784.051 | P13: 8 | Q13: =(B42-B46)/B46 -> -0.0026678704 | R13: =(E43-E47)/E47 -> 0.045603443 | S13: =(H40-H44)/H44 -> 0.029209778 | T13: =(K43-K47)/K47 -> 0.013093779 | U13: =(N42-N46)/N46 -> 0.0067784295
A14: 45736 | B14: 41953.324 | D14: 45736 | E14: 3116.068 | G14: 45735 | H14: 253.91364 | J14: 45736 | K14: 600.04123 | M14: 45736 | N14: 17691.626 | P14: 9 | Q14: =(B47-B51)/B51 -> -0.0037777404 | R14: =(E48-E49)/E49 -> 0.0011093822 | S14: =(H45-H49)/H49 -> -0.0042781157 | T14: =(K48-K52)/K52 -> 0.0060592133 | U14: =(N47-N51)/N51 -> 0.014766283
A15: 45735 | B15: 41964.634 | D15: 45735 | E15: 3187.7617 | G15: 45734 | H15: 253.55366 | J15: 45735 | K15: 605.40688 | M15: 45735 | N15: 17750.79 | P15: 10 | Q15: =(B52-B55)/B55 -> 0.0090501648 | R15: =(E50-E54)/E54 -> 0.0061786527 | S15: =(H50-H54)/H54 -> 0.023896594 | T15: =(K53-K57)/K57 -> 0.019511192 | U15: =(N52-N55)/N55 -> 0.0099976823
A16: 45734 | B16: 41581.314 | D16: 45734 | E16: 3184.4834 | G16: 45733 | H16: 250.63012 | J16: 45734 | K16: 606.56796 | M16: 45734 | N16: 17504.117 | P16: 11 | Q16: =(B56-B60)/B60 -> 0.028151147 | R16: =(E55-E59)/E59 -> 0.037600043 | S16: =(H55-H58)/H58 -> 0.010020654 | T16: =(K58-K62)/K62 -> 0.032076722 | U16: =(N56-N60)/N60 -> 0.028399733
A17: 45733 | B17: 41841.635 | D17: 45733 | E17: 3107.7379 | G17: 45730 | H17: 249.31436 | J17: 45733 | K17: 601.67964 | M17: 45733 | N17: 17808.664 | P17: 12 | Q17: =(B61-B64)/B64 -> -0.017985861 | R17: =(E60-E64)/E64 -> -0.033186097 | S17: =(H59-H63)/H63 -> -0.0035367073 | T17: =(K63-K67)/K67 -> -0.01697599 | U17: =(N61-N64)/N64 -> -0.035406679
A18: 45730 | B18: 41488.189 | D18: 45730 | E18: 3082.5417 | G18: 45729 | H18: 248.90082 | J18: 45730 | K18: 594.64752 | M18: 45730 | N18: 17754.086 | P18: 13 | Q18: =(B65-B68)/B68 -> 0.0037207242 | R18: =(E65-E68)/E68 -> -0.01549893 | S18: 0 | T18: =(K68-K71)/K71 -> -0.0029614053 | U18: =(N65-N68)/N68 -> 0.0069222296
A19: 45729 | B19: 40813.569 | D19: 45729 | E19: 3018.9856 | G19: 45728 | H19: 248.35811 | J19: 45729 | K19: 586.48493 | M19: 45729 | N19: 17303.014 | P19: 14 | Q19: =(B69-B72)/B72 -> 0.0019870254 | R19: =(E69-E71)/E71 -> 0.011481887 | S19: =(H65-H69)/H69 -> 0.024293475 | T19: =(K72-K74)/K74 -> 0.010625235 | U19: =(N69-N72)/N72 -> -0.0021681887
A20: 45728 | B20: 41350.929 | D20: 45728 | E20: 3037.7148 | G20: 45727 | H20: 248.98904 | J20: 45728 | K20: 589.20543 | M20: 45728 | N20: 17648.45 | P20: 15 | Q20: =(B73-B77)/B77 -> -0.020065691 | R20: =(E72-E76)/E76 -> -0.0039062647 | S20: =(H70-H74)/H74 -> -0.033321979 | T20: =(K75-K79)/K79 -> -0.033946092 | U20: =(N73-N77)/N77 -> -0.029805554
A21: 45727 | B21: 41433.482 | D21: 45727 | E21: 3060.6069 | G21: 45726 | H21: 251.44825 | J21: 45727 | K21: 586.17565 | M21: 45727 | N21: 17436.095 | P21: 16 | Q21: =(B78-B82)/B82 -> -0.0129245 | R21: =(E77-E81)/E81 -> -0.021806593 | S21: =(H75-H79)/H79 -> -0.0081579696 | T21: =(K80-K84)/K84 -> -0.01384466 | U21: =(N78-N82)/N82 -> 0.0096284635
A22: 45726 | B22: 41911.709 | D22: 45726 | E22: 3061.5687 | G22: 45723 | H22: 249.18712 | J22: 45726 | K22: 591.64419 | M22: 45726 | N22: 17468.321 | P22: 17 | Q22: =(B83-B87)/B87 -> -0.0031144816 | R22: =(E82-E86)/E86 -> 0.016454436 | S22: =(H80-H84)/H84 -> 0.012035034 | T22: =(K85-K89)/K89 -> 0.020210315 | U22: =(N83-N87)/N87 -> 0.023491405
A23: 45723 | B23: 42801.716 | D23: 45723 | E23: 3118.5313 | G23: 45722 | H23: 254.84914 | J23: 45723 | K23: 599.38907 | M23: 45723 | N23: 18196.221 | P23: 18 | Q23: =(B88-B91)/B91 -> 0.003891217 | R23: =(E87-E91)/E91 -> 0.014287429 | S23: =(H85-H89)/H89 -> 0.014590939 | T23: =(K90-K94)/K94 -> 0.01063129 | U23: =(N88-N91)/N91 -> 0.0085716302
A24: 45722 | B24: 42579.076 | D24: 45722 | E24: 3135.6181 | G24: 45721 | H24: 251.33154 | J24: 45722 | K24: 599.42419 | M24: 45722 | N24: 18069.255 | P24: 19 | Q24: =(B92-B96)/B96 -> 0.020901569 | R24: =(E92-E96)/E96 -> -0.017769941 | S24: =(H90-H94)/H94 -> 0.0010657355 | T24: =(K95-K99)/K99 -> -0.0061630097 | U24: =(N92-N96)/N96 -> 0.011273265
A25: 45721 | B25: 43006.592 | D25: 45721 | E25: 3036.3043 | G25: 45720 | H25: 249.20681 | J25: 45721 | K25: 600.02374 | M25: 45721 | N25: 18552.734 | P25: 20 | Q25: =(B97-B101)/B101 -> -0.019148489 | R25: =(E97-E101)/E101 -> -0.050144372 | S25: =(H95-H99)/H99 -> -0.026512987 | T25: =(K100-K104)/K104 -> -0.028476477 | U25: =(N97-N101)/N101 -> -0.032056044
A26: 45720 | B26: 42520.988 | D26: 45720 | E26: 2952.0768 | G26: 45719 | H26: 252.74562 | J26: 45720 | K26: 585.4537 | M26: 45720 | N26: 18285.163 | P26: 21 | Q26: =(B102-B106)/B106 -> 0.052504174 | R26: =(E102-E106)/E106 -> 0.0075007184 | S26: =(H100-H103)/H103 -> 0.019724752 | T26: =(K105-K109)/K109 -> -0.019611951 | U26: =(N102-N106)/N106 -> 0.060879757
A27: 45719 | B27: 43191.244 | D27: 45719 | E27: 2958.3209 | G27: 45716 | H27: 246.71647 | J27: 45719 | K27: 590.49966 | M27: 45719 | N27: 18350.191 | P27: 22 | Q27: =(B107-B111)/B111 -> -0.0079121785 | R27: =(E107-E111)/E111 -> -0.0052153374 | S27: =(H104-H108)/H108 -> -0.012361835 | T27: =(K110-K114)/K114 -> -0.01729418 | U27: =(N107-N111)/N111 -> -0.017626362
A28: 45716 | B28: 43840.908 | D28: 45716 | E28: 2949.4003 | G28: 45715 | H28: 255.38164 | J28: 45716 | K28: 578.08188 | M28: 45716 | N28: 18847.279 | P28: 23 | Q28: =(B112-B116)/B116 -> -0.01903475 | R28: =(E112-E116)/E116 -> 0.0058163445 | S28: =(H109-H113)/H113 -> -0.036109349 | T28: =(K115-K119)/K119 -> -0.0072256185 | U28: =(N112-N116)/N116 -> -0.0011542068
A29: 45715 | B29: 43239.497 | D29: 45715 | E29: 3049.6426 | G29: 45714 | H29: 255.85169 | J29: 45715 | K29: 579.2248 | M29: 45715 | N29: 18544.419 | P29: 24 | Q29: =(B117-B121)/B121 -> 0.0048922772 | R29: =(E117-E121)/E121 -> -0.014464257 | S29: =(H114-H117)/H117 -> -0.025427742 | T29: =(K120-K124)/K124 -> -0.0035077992 | U29: =(N117-N121)/N121 -> -0.00070973483
A30: 45714 | B30: 43433.124 | D30: 45714 | E30: 3059.9738 | G30: 45713 | H30: 256.59502 | J30: 45714 | K30: 586.69923 | M30: 45714 | N30: 19075.263 | P30: 25 | Q30: =(B122-B126)/B126 -> 0.021681398 | R30: =(E122-E125)/E125 -> -0.080477577 | S30: =(H118-H122)/H122 -> 0.0005278027 | T30: =(K125-K129)/K129 -> 0.001416717 | U30: =(N122-N126)/N126 -> 0.023378445
A31: 45713 | B31: 43621.157 | D31: 45713 | E31: 2963.0704 | G31: 45709 | H31: 259.74238 | J31: 45713 | K31: 582.63246 | M31: 45713 | N31: 19026.386 | P31: 26 | Q31: =(B127-B131)/B131 -> 0.00053388425 | R31: =(E126-E129)/E129 -> 0.076759933 | S31: =(H123-H127)/H127 -> -0.015990118 | T31: =(K130-K134)/K134 -> -0.022355326 | U31: =(N127-N131)/N131 -> -0.0028215141
A32: 45712 | B32: 43461.215 | D32: 45712 | E32: 3002.1749 | G32: 45708 | H32: 258.49121 | J32: 45712 | K32: 579.18093 | M32: 45712 | N32: 19286.925 | P32: 27 | Q32: =(B132-B136)/B136 -> 0.0044712607 | R32: =(E130-E134)/E134 -> 0.13270917 | S32: =(H128-H131)/H131 -> 0.057318227 | T32: =(K135-K139)/K139 -> 0.027469046 | U32: =(N132-N136)/N136 -> 0.0080848902
A33: 45709 | B33: 43428.022 | D33: 45709 | E33: 3021.8058 | G33: 45707 | H33: 258.56348 | J33: 45709 | K33: 579.21377 | M33: 45709 | N33: 19524.005 | P33: 28 | Q33: =(B137-B141)/B141 -> 0.010602061 | R33: =(E135-E138)/E138 -> 0.04840096 | S33: =(H132-H135)/H135 -> 0.031070869 | T33: =(K140-K144)/K144 -> 0.0010354605 | U33: =(N137-N141)/N141 -> 0.020247353
A34: 45708 | B34: 44176.65 | D34: 45708 | E34: 2903.3062 | G34: 45706 | H34: 258.27294 | J34: 45708 | K34: 578.56108 | M34: 45708 | N34: 19962.362 | P34: 29 | Q34: =(B142-B146)/B146 -> 0.013818337 | R34: =(E139-E143)/E143 -> 0.0097244053 | S34: =(H136-H140)/H140 -> 0.026963002 | T34: =(K145-K149)/K149 -> 0.014129333 | U34: =(N142-N146)/N146 -> 0.04734331
A35: 45707 | B35: 44627.586 | D35: 45707 | E35: 2950.2687 | G35: 45705 | H35: 258.57591 | J35: 45707 | K35: 575.34389 | M35: 45707 | N35: 20056.253 | P35: 30 | Q35: =(B147-B150)/B150 -> -0.014449704 | R35: =(E144-E147)/E147 -> -0.013606782 | S35: =(H141-H145)/H145 -> -0.029071308 | T35: =(K150-K154)/K154 -> -0.033965418 | U35: =(N147-N150)/N150 -> -0.025995463
A36: 45706 | B36: 44556.343 | D36: 45706 | E36: 2955.4068 | G36: 45702 | H36: 257.00407 | J36: 45706 | K36: 581.96156 | M36: 45706 | N36: 20041.261 | P36: 31 | Q36: =(B151-B155)/B155 -> 0.0078216093 | R36: =(E148-E152)/E152 -> 0.010512552 | S36: =(H146-H150)/H150 -> 0.0027257734 | T36: =(K155-K159)/K159 -> 0.0031668205 | U36: =(N151-N155)/N155 -> -0.00068493518
A37: 45702 | B37: 44546.078 | D37: 45705 | E37: 2906.8957 | G37: 45701 | H37: 258.2726 | J37: 45705 | K37: 582.18905 | M37: 45702 | N37: 20026.773 | P37: 32 | Q37: =(B156-B160)/B160 -> 0.006811113 | R37: =(E153-E157)/E157 -> 0.0015076643 | S37: =(H151-H155)/H155 -> 0.041731111 | T37: =(K160-K164)/K164 -> 0.016411074 | U37: =(N156-N160)/N160 -> 5.72251e-05
A38: 45701 | B38: 44711.429 | D38: 45702 | E38: 2905.9287 | G38: 45700 | H38: 252.33923 | J38: 45702 | K38: 579.5321 | M38: 45701 | N38: 19945.644 | P38: 33 | Q38: =(B161-B165)/B165 -> 0.033100866 | R38: =(E158-E162)/E162 -> 0.01815623 | S38: =(H156-H159)/H159 -> 0.045101672 | T38: =(K165-K169)/K169 -> 0.033883208 | U38: =(N161-N165)/N165 -> 0.050719911
A39: 45700 | B39: 44368.556 | D39: 45701 | E39: 2800.9514 | G39: 45698 | H39: 255.28765 | J39: 45701 | K39: 579.44248 | M39: 45700 | N39: 19649.951 | P39: 34 | Q39: =(B166-B170)/B170 -> 0.020521891 | R39: =(E163-E167)/E167 -> 0.022286271 | S39: =(H160-H164)/H164 -> 0.094844755 | T39: =(K170-K174)/K174 -> 0.021557971 | U39: =(N166-N170)/N170 -> 0.033655385
A40: 45699 | B40: 44593.655 | D40: 45700 | E40: 2806.0028 | G40: 45695 | H40: 256.18904 | J40: 45700 | K40: 568.70257 | M40: 45699 | N40: 19643.856 | P40: 35 | Q40: =(B171-B175)/B175 -> -0.019799574 | R40: =(E168-E172)/E172 -> -0.016533797 | S40: =(H165-H169)/H169 -> -0.018934981 | T40: =(K175-K179)/K179 -> -0.019237137 | U40: =(N171-N175)/N175 -> -0.034198626
A41: 45698 | B41: 44470.41 | D41: 45699 | E41: 2733.0185 | G41: 45694 | H41: 257.96705 | J41: 45699 | K41: 566.87905 | M41: 45698 | N41: 19714.27 | P41: 36 | Q41: =(B176-B180)/B180 -> 0.0043027442 | R41: =(E173-E177)/E177 -> -0.034785892 | S41: =(H170-H174)/H174 -> -0.028482077 | T41: =(K180-K184)/K184 -> -0.0067276219 | U41: =(N176-N180)/N180 -> -0.036078498
A42: 45695 | B42: 44303.399 | D42: 45698 | E42: 2763.2668 | G42: 45693 | H42: 254.46579 | J42: 45698 | K42: 562.62432 | M42: 45695 | N42: 19523.402 | P42: 37 | Q42: =(B181-B185)/B185 -> 0.001885351 | R42: =(E178-E182)/E182 -> -0.033665274 | S42: =(H175-H178)/H178 -> -0.024107985 | T42: =(K185-K189)/K189 -> -0.018301057 | U42: =(N181-N185)/N185 -> -0.040363965
...

Sheet Venerdì
V1: RENDIMENTI SETTIMANALI
B2: Date | C2: DJIA | F2: Date | G2: HSI | J2: Date | K2: N225E | N2: Date | O2: STOXX | R2: Date | S2: IXIC | V2: settimana | W2: DJIA | X2: HSI | Y2: N225E | Z2: STOXX | AA2: IXIC
A3: =WEEKDAY(B3,2) -> 5 | B3: 45807 | C3: 42215.73 | E3: =WEEKDAY(F3,2) -> 5 | F3: 45807 | G3: 2969.99 | I3: =WEEKDAY(J3,2) -> 5 | J3: 45807 | K3: 263.3 | M3: =WEEKDAY(N3,2) -> 5 | N3: 45807 | O3: 626.24 | Q3: =WEEKDAY(R3,2) -> 5 | R3: 45807 | S3: 19175.87 | V3: 113 | W3: =(C3-C4)/C4 -> 0.014726317 | X3: =(G3-G4)/G4 -> -0.014356592 | Y3: =(K3-K4)/K4 -> 0.0099731492 | Z3: =(O3-O4)/O4 -> 0.01089606 | AA3: =(S3-S4)/S4 -> 0.02341117
A4: =WEEKDAY(B4,2) -> 5 | B4: 45800 | C4: 41603.07 | E4: =WEEKDAY(F4,2) -> 5 | F4: 45800 | G4: 3013.25 | I4: =WEEKDAY(J4,2) -> 5 | J4: 45800 | K4: 260.7 | M4: =WEEKDAY(N4,2) -> 5 | N4: 45800 | O4: 619.49 | Q4: =WEEKDAY(R4,2) -> 5 | R4: 45800 | S4: 18737.21 | V4: 112 | W4: =(C4-C5)/C5 -> -0.024655408 | X4: =(G4-G5)/G5 -> 0.0085618559 | Y4: =(K4-K5)/K5 -> 0.0055542698 | Z4: =(O4-O5)/O5 -> 0.010356525 | AA4: =(S4-S5)/S5 -> -0.02466751
A5: =WEEKDAY(B5,2) -> 5 | B5: 45793 | C5: 42654.74 | E5: =WEEKDAY(F5,2) -> 5 | F5: 45793 | G5: 2987.67 | I5: =WEEKDAY(J5,2) -> 5 | J5: 45793 | K5: 259.26 | M5: =WEEKDAY(N5,2) -> 5 | N5: 45793 | O5: 613.14 | Q5: =WEEKDAY(R5,2) -> 5 | R5: 45793 | S5: 19211.1 | V5: 111 | W5: =(C5-C6)/C6 -> 0.034069845 | X5: =(G5-G6)/G6 -> 0.01627305 | Y5: =(K5-K6)/K6 -> 0.0047279492 | Z5: =(O5-O6)/O6 -> 0.013387545 | AA5: =(S5-S6)/S6 -> 0.071514626
A6: =WEEKDAY(B6,2) -> 5 | B6: 45786 | C6: 41249.38 | E6: =WEEKDAY(F6,2) -> 5 | F6: 45786 | G6: 2939.83 | I6: =WEEKDAY(J6,2) -> 5 | J6: 45786 | K6: 258.04 | M6: =WEEKDAY(N6,2) -> 5 | N6: 45786 | O6: 605.04 | Q6: =WEEKDAY(R6,2) -> 5 | R6: 45786 | S6: 17928.92 | V6: 110 | W6: =(C6-C7)/C7 -> -0.0016470047 | X6: =(G6-G7)/G7 -> 0.01239742 | Y6: =(K6-K7)/K7 -> 0.015385826 | Z6: =(O6-O7)/O7 -> -0.0014193761 | AA6: =(S6-S7)/S7 -> -0.0027150258
A7: =WEEKDAY(B7,2) -> 5 | B7: 45779 | C7: 41317.43 | E7: =WEEKDAY(F7,2) -> 5 | F7: 45779 | G7: 2903.83 | I7: =WEEKDAY(J7,2) -> 5 | J7: 45779 | K7: 254.13 | M7: =WEEKDAY(N7,2) -> 5 | N7: 45779 | O7: 605.9 | Q7: =WEEKDAY(R7,2) -> 5 | R7: 45779 | S7: 17977.73 | V7: 109 | W7: =(C7-C8)/C8 -> 0.030013088 | X7: =(G7-G8)/G8 -> 0.024734097 | Y7: =(K7-K8)/K8 -> 0.022532491 | Z7: =(O7-O8)/O8 -> 0.024448803 | AA7: =(S7-S8)/S8 -> 0.034216882
A8: =WEEKDAY(B8,2) -> 5 | B8: 45772 | C8: 40113.5 | E8: =WEEKDAY(F8,2) -> 5 | F8: 45772 | G8: 2833.74 | I8: =WEEKDAY(J8,2) -> 5 | J8: 45772 | K8: 248.53 | M8: =WEEKDAY(N8,2) -> 5 | N8: 45772 | O8: 591.44 | Q8: =WEEKDAY(R8,2) -> 5 | R8: 45772 | S8: 17382.94 | V8: 108 | W8: =(C8-C9)/C9 -> 0.024813865 | X8: =(G8-G9)/G9 -> 0.02803223 | Y8: =(K8-K9)/K9 -> 0.017356421 | Z8: =(O8-O9)/O9 -> 0.025274763 | AA8: =(S8-S9)/S9 -> 0.067325292
A9: =WEEKDAY(B9,2) -> 5 | B9: 45765 | C9: 39142.23 | E9: =WEEKDAY(F9,2) -> 5 | F9: 45765 | G9: 2756.47 | I9: =WEEKDAY(J9,2) -> 5 | J9: 45765 | K9: 244.29 | M9: =WEEKDAY(N9,2) -> 5 | N9: 45765 | O9: 576.86 | Q9: =WEEKDAY(R9,2) -> 5 | R9: 45765 | S9: 16286.45 | V9: 107 | W9: =(C9-C10)/C10 -> -0.026620439 | X9: =(G9-G10)/G10 -> 0.021864771 | Y9: =(K9-K10)/K10 -> 0.043840533 | Z9: =(O9-O10)/O10 -> 0.043127611 | AA9: =(S9-S10)/S10 -> -0.026189784
A10: =WEEKDAY(B10,2) -> 5 | B10: 45758 | C10: 40212.71 | E10: =WEEKDAY(F10,2) -> 5 | F10: 45758 | G10: 2697.49 | I10: =WEEKDAY(J10,2) -> 5 | J10: 45758 | K10: 234.03 | M10: =WEEKDAY(N10,2) -> 5 | N10: 45758 | O10: 553.01 | Q10: =WEEKDAY(R10,2) -> 5 | R10: 45758 | S10: 16724.46 | V10: 106 | W10: =(C10-C11)/C11 -> 0.049533001 | X10: =(G10-G11)/G11 -> -0.082230418 | Y10: =(K10-K11)/K11 -> 0.01769873 | Z10: =(O10-O11)/O11 -> 0.017067294 | AA10: =(S10-S11)/S11 -> 0.072920536
A11: =WEEKDAY(B11,2) -> 5 | B11: 45751 | C11: 38314.86 | E11: =WEEKDAY(F11,2) -> 5 | F11: 45751 | G11: 2939.18 | I11: =WEEKDAY(J11,2) -> 5 | J11: 45751 | K11: 229.96 | M11: =WEEKDAY(N11,2) -> 5 | N11: 45751 | O11: 543.73 | Q11: =WEEKDAY(R11,2) -> 5 | R11: 45751 | S11: 15587.79 | V11: 105 | W11: =(C11-C12)/C12 -> -0.078613028 | X11: =(G11-G12)/G12 -> -0.024170147 | Y11: =(K11-K12)/K12 -> -0.071918638 | Z11: =(O11-O12)/O12 -> -0.073603326 | AA11: =(S11-S12)/S12 -> -0.10016747
A12: =WEEKDAY(B12,2) -> 5 | B12: 45744 | C12: 41583.896 | E12: =WEEKDAY(F12,2) -> 5 | F12: 45744 | G12: 3011.98 | I12: =WEEKDAY(J12,2) -> 5 | J12: 45744 | K12: 247.78 | M12: =WEEKDAY(N12,2) -> 5 | N12: 45744 | O12: 586.93 | Q12: =WEEKDAY(R12,2) -> 5 | R12: 45744 | S12: 17322.99 | V12: 104 | W12: =(C12-C13)/C13 -> -0.0095617355 | X12: =(G12-G13)/G13 -> -0.0116814 | Y12: =(K12-K13)/K13 -> -0.018070857 | Z12: =(O12-O13)/O13 -> -0.012583907 | AA12: =(S12-S13)/S13 -> -0.025925478
A13: =WEEKDAY(B13,2) -> 5 | B13: 45737 | C13: 41985.349 | E13: =WEEKDAY(F13,2) -> 5 | F13: 45737 | G13: 3047.58 | I13: =WEEKDAY(J13,2) -> 5 | J13: 45737 | K13: 252.34 | M13: =WEEKDAY(N13,2) -> 5 | N13: 45737 | O13: 594.41 | Q13: =WEEKDAY(R13,2) -> 5 | R13: 45737 | S13: 17784.05 | V13: 103 | W13: =(C13-C14)/C14 -> 0.011983162 | X13: =(G13-G14)/G14 -> -0.011341296 | Y13: =(K13-K14)/K14 -> 0.012153544 | Z13: =(O13-O14)/O14 -> -0.00040359876 | AA13: =(S13-S14)/S14 -> 0.0016874985
A14: =WEEKDAY(B14,2) -> 5 | B14: 45730 | C14: 41488.189 | E14: =WEEKDAY(F14,2) -> 5 | F14: 45730 | G14: 3082.54 | I14: =WEEKDAY(J14,2) -> 5 | J14: 45730 | K14: 249.31 | M14: =WEEKDAY(N14,2) -> 5 | N14: 45730 | O14: 594.65 | Q14: =WEEKDAY(R14,2) -> 5 | R14: 45730 | S14: 17754.09 | V14: 102 | W14: =(C14-C15)/C15 -> -0.030688653 | X14: =(G14-G15)/G15 -> -0.011540694 | Y14: =(K14-K15)/K15 -> 0.00048156026 | Z14: =(O14-O15)/O15 -> -0.0079080398 | AA14: =(S14-S15)/S15 -> -0.024297904
... A115: =WEEKDAY(B115,2) -> 4 | B115: 45022 | C115: 33485.289 | E115: =WEEKDAY(F115,2) -> 4 | F115: 45022 | G115: 2590.03 | I115: =WEEKDAY(J115,2) -> 5 | J115: 45023 | K115: 208.27 | M115: =WEEKDAY(N115,2) -> 4 | N115: 45022 | O115: 501.16 | Q115: =WEEKDAY(R115,2) -> 4 | R115: 45022 | S115: 12087.96 | V115: 1 | W115: =(C115-C116)/C116 -> 0.0063453154 | X115: =(G115-G116)/G116 -> -0.0034168171 | Y115: =(K115-K116)/K116 -> -0.013733011 | Z115: =(O115-O116)/O116 -> 0.0098738564 | AA115: =(S115-S116)/S116 -> -0.010959825
A116: =WEEKDAY(B116,2) -> 5 | B116: 45016 | C116: 33274.154 | E116: =WEEKDAY(F116,2) -> 5 | F116: 45016 | G116: 2598.91 | I116: =WEEKDAY(J116,2) -> 5 | J116: 45016 | K116: 211.17 | M116: =WEEKDAY(N116,2) -> 5 | N116: 45016 | O116: 496.26 | Q116: =WEEKDAY(R116,2) -> 5 | R116: 45016 | S116: 12221.91
AD117: media | AF117: mvp | AH117: rp | AJ117: t | AK117: ew
V118: MEDIA | W118: =AVERAGE(DJIA) -> 0.0022740795 | X118: =AVERAGE(HSI) -> 0.0019864499 | Y118: =AVERAGE(N225E) -> 0.0019249202 | Z118: =AVERAGE(STOXX) -> 0.0017995655 | AA118: =AVERAGE(IXIC) -> 0.0036390158 | AD118: =AVERAGE(DJIA_9) -> 0.0024022485 | AE118: 0.74039811 | AF118: =AE118*AD118 -> 0.0017786202 | AG118: 0.28097777 | AH118: =AG118*AD118 -> 0.00067497841 | AI118: 0.47234224 | AJ118: =AI118*AD118 -> 0.0011346834 | AK118: =AD118*0.2 -> 0.00048044969
V119: VARIANZA | W119: =_xlfn.VAR.S(DJIA) -> 0.00025985328 | X119: =_xlfn.VAR.S(HSI) -> 0.0011656468 | Y119: =_xlfn.VAR.S(N225E) -> 0.00078098819 | Z119: =_xlfn.VAR.S(STOXX) -> 0.00037508987 | AA119: =_xlfn.VAR.S(IXIC) -> 0.000565794 | AD119: =AVERAGE(HSI_9) -> -0.00098819268 | AE119: 0.044928717 | AF119: =AE119*AD119 -> -4.4398229e-05 | AG119: 0.13266384 | AH119: =AG119*AD119 -> -0.00013109744 | AI119: 0.051004806 | AJ119: =AI119*AD119 -> -5.0402575e-05 | AK119: =AD119*0.2 -> -0.00019763854
V120: DEV ST | W120: =_xlfn.STDEV.S(DJIA) -> 0.016119965 | X120: =_xlfn.STDEV.S(HSI) -> 0.03414157 | Y120: =_xlfn.STDEV.S(N225E) -> 0.027946166 | Z120: =_xlfn.STDEV.S(STOXX) -> 0.019367237 | AA120: =_xlfn.STDEV.S(IXIC) -> 0.023786425 | AD120: =AVERAGE(N225E_9) -> 0.0072389702 | AE120: -0.00020300168 | AF120: =AE120*AD120 -> -1.4695231e-06 | AG120: 0.16207418 | AH120: =AG120*AD120 -> 0.0011732501 | AI120: -0.25520379 | AJ120: =AI120*AD120 -> -0.0018474126 | AK120: =AD120*0.2 -> 0.001447794
AD121: =AVERAGE(STOXX_9) -> 0.007726211 | AE121: 0.23945292 | AF121: =AE121*AD121 -> 0.0018500638 | AG121: 0.2338667 | AH121: =AG121*AD121 -> 0.0018069035 | AI121: -0.012351426 | AJ121: =AI121*AD121 -> -9.5429726e-05 | AK121: =AD121*0.2 -> 0.0015452422
V122: V | W122: DJIA | X122: HSI | Y122: N225E | Z122: STOXX | AA122: IXIC | AD122: =AVERAGE(IXIC_9) -> 0.012849858 | AE122: -0.024576745 | AF122: =AE122*AD122 -> -0.00031580768 | AG122: 0.19041751 | AH122: =AG122*AD122 -> 0.0024468379 | AI122: 0.74420817 | AJ122: =AI122*AD122 -> 0.0095629691 | AK122: =AD122*0.2 -> 0.0025699715
V123: DJIA | W123: =W119 -> 0.00025985328 | X123: =_xlfn.COVARIANCE.S(DJIA,HSI) -> 0.00014522151 | Y123: =_xlfn.COVARIANCE.S(DJIA,N225E) -> 0.00020907882 | Z123: =_xlfn.COVARIANCE.S(DJIA,STOXX) -> 0.00018586625 | AA123: =_xlfn.COVARIANCE.S(DJIA,IXIC) -> 0.00024818148 | AF123: =SUM(AF118:AF122) -> 0.0032670086 | AG123: =SUM(AG118:AG122) -> 1 | AH123: =SUM(AH118:AH122) -> 0.0059708725 | AI123: =SUM(AI118:AI122) -> 1 | AJ123: =SUM(AJ118:AJ122) -> 0.0087044076 | AK123: =SUM(AK118:AK122) -> 0.0058458189
V124: HSI | W124: =X123 -> 0.00014522151 | X124: =X119 -> 0.0011656468 | Y124: =_xlfn.COVARIANCE.S(HSI,N225E) -> 0.0003547449 | Z124: =_xlfn.COVARIANCE.S(HSI,STOXX) -> 0.00034923644 | AA124: =_xlfn.COVARIANCE.S(HSI,IXIC) -> 0.00025075134
V125: N225E | W125: =Y123 -> 0.00020907882 | X125: =Y124 -> 0.0003547449 | Y125: =Y119 -> 0.00078098819 | Z125: =_xlfn.COVARIANCE.S(N225E,STOXX) -> 0.00031963276 | AA125: =_xlfn.COVARIANCE.S(N225E,IXIC) -> 0.00040015408 | AD125: dev st
V126: STOXX | W126: =Z123 -> 0.00018586625 | X126: =Z124 -> 0.00034923644 | Y126: =Z125 -> 0.00031963276 | Z126: =Z119 -> 0.00037508987 | AA126: =_xlfn.COVARIANCE.S(STOXX,IXIC) -> 0.0002349161 | AD126: =_xlfn.STDEV.S(DJIA_9) -> 0.039992141 | AE126: 0.74039811 | AF126: =AD126*AE126 -> 0.029610106 | AG126: 0.28097777 | AH126: =AD126*AG126 -> 0.011236903 | AI126: 0.47234224 | AJ126: =AD126*AI126 -> 0.018889978 | AK126: =AD126*0.2 -> 0.0079984282
V127: IXIC | W127: =AA123 -> 0.00024818148 | X127: =AA124 -> 0.00025075134 | Y127: =AA125 -> 0.00040015408 | Z127: =AA126 -> 0.0002349161 | AA127: =AA119 -> 0.000565794 | AD127: =_xlfn.STDEV.S(HSI_9) -> 0.035197343 | AE127: 0.044928717 | AF127: =AD127*AE127 -> 0.0015813715 | AG127: 0.13266384 | AH127: =AD127*AG127 -> 0.0046694148 | AI127: 0.051004806 | AJ127: =AD127*AI127 -> 0.0017952337 | AK127: =AD127*0.2 -> 0.0070394687
AD128: =_xlfn.STDEV.S(N225E_9) -> 0.031887013 | AE128: -0.00020300168 | AF128: =AD128*AE128 -> -6.4731173e-06 | AG128: 0.16207418 | AH128: =AD128*AG128 -> 0.0051680614 | AI128: -0.25520379 | AJ128: =AD128*AI128 -> -0.0081376865 | AK128: =AD128*0.2 -> 0.0063774026
V129: e | W129: {=TRANSPOSE(W118:AA118)} -> 0.0022740795 | AD129: =_xlfn.STDEV.S(STOXX_9) -> 0.032930351 | AE129: 0.23945292 | AF129: =AD129*AE129 -> 0.0078852688 | AG129: 0.2338667 | AH129: =AD129*AG129 -> 0.0077013126 | AI129: -0.012351426 | AJ129: =AD129*AI129 -> -0.00040673681 | AK129: =AD129*0.2 -> 0.0065860702
W130: 0.0019864499 | AD130: =_xlfn.STDEV.S(IXIC_9) -> 0.05758964 | AE130: -0.024576745 | AF130: =AD130*AE130 -> -0.0014153659 | AG130: 0.19041751 | AH130: =AD130*AG130 -> 0.010966076 | AI130: 0.74420817 | AJ130: =AD130*AI130 -> 0.04285868 | AK130: =AD130*0.2 -> 0.011517928
W131: 0.0019249202 | AF131: =SUM(AF126:AF130) -> 0.037654907 | AH131: =SUM(AH126:AH130) -> 0.039741767 | AJ131: =SUM(AJ126:AJ130) -> 0.054999468 | AK131: =SUM(AK126:AK130) -> 0.039519298
W132: 0.0017995655
W133: 0.0036390158 | AD133: sharpe ratio

Sheet Portafogli
A1: investimento | B1: 100
A3: V | B3: {=V} -> 0.00025985328 | C3: 0.00014522151 | D3: 0.00020907882 | E3: 0.00018586625 | F3: 0.00024818148 | K3: w_EW | L3: =1/5 -> 0.2 | N3: {=B1*L3:L7} -> 20
B4: 0.00014522151 | C4: 0.0011656468 | D4: 0.0003547449 | E4: 0.00034923644 | F4: 0.00025075134 | L4: =1/5 -> 0.2 | N4: 20
B5: 0.00020907882 | C5: 0.0003547449 | D5: 0.00078098819 | E5: 0.00031963276 | F5: 0.00040015408 | L5: =1/5 -> 0.2 | N5: 20
B6: 0.00018586625 | C6: 0.00034923644 | D6: 0.00031963276 | E6: 0.00037508987 | F6: 0.0002349161 | L6: =1/5 -> 0.2 | N6: 20
B7: 0.00024818148 | C7: 0.00025075134 | D7: 0.00040015408 | E7: 0.0002349161 | F7: 0.000565794 | L7: =1/5 -> 0.2 | N7: 20
L8: =SUM(L3:L7) -> 1
A11: V^(-1) | B11: {=MINVERSE(V)} -> 8045.052 | C11: 353.8536 | D11: 202.66976 | E11: -2825.2347 | F11: -2656.0341 | H11: 1I | I11: 1 | K11: w_MVP | L11: {=MMULT(_xlfn.ANCHORARRAY(B11),I11:I15)/I17} -> 0.74039811 | N11: {=B1*_xlfn.ANCHORARRAY(L11)} -> 74.039811
B12: 353.8536 | C12: 1214.9024 | D12: -112.57536 | E12: -1116.2929 | F12: -150.54178 | I12: 1 | L12: 0.044928717 | N12: 4.4928717
B13: 202.66976 | C13: -112.57536 | D13: 2438.1316 | E13: -1309.3663 | F13: -1219.7152 | I13: 1 | L13: -0.00020300168 | N13: -0.020300168
B14: -2825.2347 | C14: -1116.2929 | D14: -1309.3663 | E14: 6155.9246 | F14: 104.11089 | I14: 1 | L14: 0.23945292 | N14: 23.945292
B15: -2656.0341 | C15: -150.54178 | D15: -1219.7152 | E15: 104.11089 | F15: 3818.6048 | I15: 1 | L15: -0.024576745 | N15: -2.4576745
L16: =SUM(L11:L15) -> 1
A17: 1I_T | B17: 1 | C17: 1 | D17: 1 | E17: 1 | F17: 1 | H17: C | I17: {=MMULT(MMULT(B17:F17,_xlfn.ANCHORARRAY(B11)),I11:I15)} -> 4214.3632
A20: SIGMA | B20: =_xlfn.STDEV.S(DJIA) -> 0.016119965 | C20: =_xlfn.STDEV.S(HSI) -> 0.03414157 | D20: =_xlfn.STDEV.S(N225E) -> 0.027946166 | E20: =_xlfn.STDEV.S(STOXX) -> 0.019367237 | F20: =_xlfn.STDEV.S(IXIC) -> 0.023786425 | K20: w_RP | L20: {=TRANSPOSE(_xlfn.ANCHORARRAY(B26)/I26)} -> 0.28097777 | N20: {=B1*_xlfn.ANCHORARRAY(L20)} -> 28.097777
B21: formula "DEV.ST.C" | L21: 0.13266384 | N21: 13.266384
A22: SIGMA | B22: =SQRT(B3) -> 0.016119965 | C22: =SQRT(C4) -> 0.03414157 | D22: =SQRT(D5) -> 0.027946166 | E22: =SQRT(E6) -> 0.019367237 | F22: =SQRT(F7) -> 0.023786425 | L22: 0.16207418 | N22: 16.207418
B23: formula "RADQ" | L23: 0.2338667 | N23: 23.38667
L24: 0.19041751 | N24: 19.041751
L25: =SUM(L20:L24) -> 1
A26: SIGMA^(-1) | B26: {=1/B20:F20} -> 62.034873 | C26: 29.289807 | D26: 35.783084 | E26: 51.633591 | F26: 42.040786 | H26: SOMMA | I26: =SUM(_xlfn.ANCHORARRAY(B26)) -> 220.78214
A29: i | B29: 0.02 | D29: NUM | E29: V^(-1) * (e - rf*1I) | K29: w_T | L29: {=_xlfn.ANCHORARRAY(E30)/E37} -> 0.47234224 | N29: {=B1*_xlfn.ANCHORARRAY(L29)} -> 47.234224
A30: q | B30: 52 | E30: {=MMULT(_xlfn.ANCHORARRAY(B11),_xlfn.ANCHORARRAY(B33))} -> 3.4500776 | L30: 0.051004806 | N30: 5.1004806
A31: r_sett | B31: =(1+B29)^(1/B30)-1 -> 0.00038089228 | E31: 0.37254881 | L31: -0.25520379 | N31: -25.520379
E32: -1.864057 | L32: -0.012351426 | N32: -1.2351426
A33: e - rf*1I | B33: {=e-B31*I11:I15} -> 0.0018931872 | E33: -0.090217168 | L33: 0.74420817 | N33: 74.420817
B34: 0.0016055577 | E34: 5.4358381 | L34: =SUM(L29:L33) -> 1
B35: 0.0015440279
B36: 0.0014186733 | D36: DEN | E36: 1I_T * V^(-1) * (e - rf*1I)
B37: 0.0032581236 | E37: {=MMULT(MMULT(B17:F17,_xlfn.ANCHORARRAY(B11)),_xlfn.ANCHORARRAY(B33))} -> 7.3041903

Sheet Consegna
B2: Date | C2: DJIA | D2: HSI | E2: N225E | F2: STOXX | G2: IXIC | K2: DJIA | L2: HSI | M2: N225E | N2: STOXX | O2: IXIC
B3: 45807 | C3: 42215.73 | D3: 2969.99 | E3: 263.3 | F3: 626.24 | G3: 19175.87 | J3: settimana | K3: RENDIMENTI SETTIMANALI
B4: 45800 | C4: 41603.07 | D4: 3013.25 | E4: 260.7 | F4: 619.49 | G4: 18737.21 | J4: 113 | K4: =(C3-C4)/C4 -> 0.014726317 | L4: =(D3-D4)/D4 -> -0.014356592 | M4: =(E3-E4)/E4 -> 0.0099731492 | N4: =(F3-F4)/F4 -> 0.01089606 | O4: =(G3-G4)/G4 -> 0.02341117
B5: 45793 | C5: 42654.74 | D5: 2987.67 | E5: 259.26 | F5: 613.14 | G5: 19211.1 | J5: 112 | K5: =(C4-C5)/C5 -> -0.024655408 | L5: =(D4-D5)/D5 -> 0.0085618559 | M5: =(E4-E5)/E5 -> 0.0055542698 | N5: =(F4-F5)/F5 -> 0.010356525 | O5: =(G4-G5)/G5 -> -0.02466751
B6: 45786 | C6: 41249.38 | D6: 2939.83 | E6: 258.04 | F6: 605.04 | G6: 17928.92 | J6: 111 | K6: =(C5-C6)/C6 -> 0.034069845 | L6: =(D5-D6)/D6 -> 0.01627305 | M6: =(E5-E6)/E6 -> 0.0047279492 | N6: =(F5-F6)/F6 -> 0.013387545 | O6: =(G5-G6)/G6 -> 0.071514626
B7: 45779 | C7: 41317.43 | D7: 2903.83 | E7: 254.13 | F7: 605.9 | G7: 17977.73 | J7: 110 | K7: =(C6-C7)/C7 -> -0.0016470047 | L7: =(D6-D7)/D7 -> 0.01239742 | M7: =(E6-E7)/E7 -> 0.015385826 | N7: =(F6-F7)/F7 -> -0.0014193761 | O7: =(G6-G7)/G7 -> -0.0027150258
B8: 45772 | C8: 40113.5 | D8: 2833.74 | E8: 248.53 | F8: 591.44 | G8: 17382.94 | J8: 109 | K8: =(C7-C8)/C8 -> 0.030013088 | L8: =(D7-D8)/D8 -> 0.024734097 | M8: =(E7-E8)/E8 -> 0.022532491 | N8: =(F7-F8)/F8 -> 0.024448803 | O8: =(G7-G8)/G8 -> 0.034216882
B9: 45765 | C9: 39142.23 | D9: 2756.47 | E9: 244.29 | F9: 576.86 | G9: 16286.45 | J9: 108 | K9: =(C8-C9)/C9 -> 0.024813865 | L9: =(D8-D9)/D9 -> 0.02803223 | M9: =(E8-E9)/E9 -> 0.017356421 | N9: =(F8-F9)/F9 -> 0.025274763 | O9: =(G8-G9)/G9 -> 0.067325292
B10: 45758 | C10: 40212.71 | D10: 2697.49 | E10: 234.03 | F10: 553.01 | G10: 16724.46 | J10: 107 | K10: =(C9-C10)/C10 -> -0.026620439 | L10: =(D9-D10)/D10 -> 0.021864771 | M10: =(E9-E10)/E10 -> 0.043840533 | N10: =(F9-F10)/F10 -> 0.043127611 | O10: =(G9-G10)/G10 -> -0.026189784
B11: 45751 | C11: 38314.86 | D11: 2939.18 | E11: 229.96 | F11: 543.73 | G11: 15587.79 | J11: 106 | K11: =(C10-C11)/C11 -> 0.049533001 | L11: =(D10-D11)/D11 -> -0.082230418 | M11: =(E10-E11)/E11 -> 0.01769873 | N11: =(F10-F11)/F11 -> 0.017067294 | O11: =(G10-G11)/G11 -> 0.072920536
B12: 45744 | C12: 41583.896 | D12: 3011.98 | E12: 247.78 | F12: 586.93 | G12: 17322.99 | J12: 105 | K12: =(C11-C12)/C12 -> -0.078613028 | L12: =(D11-D12)/D12 -> -0.024170147 | M12: =(E11-E12)/E12 -> -0.071918638 | N12: =(F11-F12)/F12 -> -0.073603326 | O12: =(G11-G12)/G12 -> -0.10016747
K13: rendimenti medi
K14: =AVERAGE(K4:K12) -> 0.0024022485 | L14: =AVERAGE(L4:L12) -> -0.00098819268 | M14: =AVERAGE(M4:M12) -> 0.0072389702 | N14: =AVERAGE(N4:N12) -> 0.007726211 | O14: =AVERAGE(O4:O12) -> 0.012849858
B15: Portafogli | C15: DJIA | D15: HSI | E15: N225 | F15: STOXX | G15: ^IXIC | K15: deviazioni standard
B16: 1/N | C16: 0.2 | D16: 0.2 | E16: 0.2 | F16: 0.2 | G16: 0.2 | K16: =_xlfn.STDEV.S(K4:K12) -> 0.039992141 | L16: =_xlfn.STDEV.S(L4:L12) -> 0.035197343 | M16: =_xlfn.STDEV.S(M4:M12) -> 0.031887013 | N16: =_xlfn.STDEV.S(N4:N12) -> 0.032930351 | O16: =_xlfn.STDEV.S(O4:O12) -> 0.05758964
B17: Varianza minima | C17: 0.74039811 | D17: 0.044928717 | E17: -0.00020300168 | F17: 0.23945292 | G17: -0.024576745
B18: Risk party (cov 0) | C18: 0.28097777 | D18: 0.13266384 | E18: 0.16207418 | F18: 0.2338667 | G18: 0.19041751
B19: Tangente | C19: 0.47234224 | D19: 0.051004806 | E19: -0.25520379 | F19: -0.012351426 | G19: 0.74420817
K21: RENDIMENTI SETTIMANALI PORTAFOGLI
B22: Portafogli | C22: pesi approssimati | K22: 1 | L22: 2 | M22: 3 | N22: 4 | O22: 5 | P22: 6 | Q22: 7 | R22: 8 | S22: 9
B23: 1/N | C23: 0.2 | D23: 0.2 | E23: 0.2 | F23: 0.2 | G23: 0.2 | J23: w_EW | K23: {=MMULT(C23:G26,TRANSPOSE(K4:O12))} -> 0.0089300208 | L23: -0.0049700533 | M23: 0.027994603 | N23: 0.0044003679 | O23: 0.027189072 | P23: 0.032560514 | Q23: 0.011204538 | R23: 0.014997829 | S23: -0.069694521
B24: Varianza minima | C24: 0.74 | D24: 0.04 | E24: 0 | F24: 0.24 | G24: -0.02 | J24: w_MVP | K24: 0.012470042 | L24: -0.014923611 | M24: 0.027645326 | N24: -0.0010092364 | O24: 0.028382424 | P24: 0.024202986 | Q24: -0.0079501119 | R24: 0.036002944 | S24: -0.074801896
B25: Risk party (cov 0) | C25: 0.28 | D25: 0.13 | E25: 0.16 | F25: 0.23 | G25: 0.19 | J25: w_RP | K25: 0.010806932 | L25: -0.0072066157 | M25: 0.029078439 | N25: 0.0027699241 | O25: 0.027348728 | P25: 0.0319741 | Q25: 0.007346474 | R25: 0.023791462 | S25: -0.072621332
B26: Tangente | C26: 0.47 | D26: 0.05 | E26: -0.26 | F26: -0.01 | G26: 0.74 | J26: w_T | K26: 0.020825826 | L26: -0.030961582 | M26: 0.068384161 | N26: -0.0061494613 | O26: 0.034560413 | P26: 0.058119427 | Q26: -0.042628623 | R26: 0.068357843 | S26: -0.092845676
K29: rendim medi | L29: rendim medi % | M29: varianza | N29: dev standard | O29: sharpe ratio
B30: tasso annuale | D30: 0.02 | J30: w_EW | K30: =AVERAGE(K23:S23)+1 -> 1.0058458 | L30: =AVERAGE(K23:S23) -> 0.0058458189 | M30: =_xlfn.VAR.S(K23:S23) -> 0.0009508976 | N30: =_xlfn.STDEV.S(K23:S23) -> 0.030836628 | O30: =(K30-D$31)/N30 -> 0.17722193
B31: tasso settimanale | D31: =((1+D30)^(1/52)) -> 1.0003809 | J31: w_MVP | K31: =AVERAGE(K24:S24)+1 -> 1.0033354 | L31: =AVERAGE(K24:S24) -> 0.0033354297 | M31: =_xlfn.VAR.S(K24:S24) -> 0.0011736824 | N31: =_xlfn.STDEV.S(K24:S24) -> 0.034259049 | O31: =(K31-D$31)/N31 -> 0.086241081
J32: w_RP | K32: =AVERAGE(K25:S25)+1 -> 1.0059209 | L32: =AVERAGE(K25:S25) -> 0.0059209013 | M32: =_xlfn.VAR.S(K25:S25) -> 0.0010463247 | N32: =_xlfn.STDEV.S(K25:S25) -> 0.032346943 | O32: =(K32-D$31)/N32 -> 0.17126839
J33: w_T | K33: =AVERAGE(K26:S26)+1 -> 1.0086291 | L33: =AVERAGE(K26:S26) -> 0.0086291475 | M33: =_xlfn.VAR.S(K26:S26) -> 0.0031398735 | N33: =_xlfn.STDEV.S(K26:S26) -> 0.056034574 | O33: =(K33-D$31)/N33 -> 0.14719939
J38: MEDIA | K38: =AVERAGE(DJIA_9) -> 0.0024022485 | L38: =AVERAGE(HSI_9) -> -0.00098819268 | M38: =AVERAGE(N225E_9) -> 0.0072389702 | N38: =AVERAGE(STOXX_9) -> 0.007726211 | O38: =AVERAGE(IXIC_9) -> 0.012849858 | Q38: Rendimenti | R38: DJIA | S38: HSI | T38: N225 | U38: STOXX | V38: ^IXIC
J39: VARIANZA | K39: =_xlfn.VAR.S(DJIA_9) -> 0.0015993714 | L39: =_xlfn.VAR.S(HSI_9) -> 0.001238853 | M39: =_xlfn.VAR.S(N225E_9) -> 0.0010167816 | N39: =_xlfn.VAR.S(STOXX_9) -> 0.001084408 | O39: =_xlfn.VAR.S(IXIC_9) -> 0.0033165666 | Q39: 45807 | R39: 0.014726317 | S39: -0.014356592 | T39: 0.0099731492 | U39: 0.01089606 | V39: 0.02341117
Q40: 45800 | R40: -0.024655408 | S40: 0.0085618559 | T40: 0.0055542698 | U40: 0.010356525 | V40: -0.02466751
Q41: 45793 | R41: 0.034069845 | S41: 0.01627305 | T41: 0.0047279492 | U41: 0.013387545 | V41: 0.071514626
J42: V | K42: DJIA | L42: HSI | M42: N225E | N42: STOXX | O42: IXIC | Q42: 45786 | R42: -0.0016470047 | S42: 0.01239742 | T42: 0.015385826 | U42: -0.0014193761 | V42: -0.0027150258
J43: DJIA | K43: =K39 -> 0.0015993714 | L43: =_xlfn.COVARIANCE.S(DJIA_9,HSI_9) -> -0.00014803691 | M43: =_xlfn.COVARIANCE.S(DJIA_9,N225E_9) -> 0.00080743313 | N43: =_xlfn.COVARIANCE.S(DJIA_9,STOXX_9) -> 0.00088012108 | O43: =_xlfn.COVARIANCE.S(DJIA_9,IXIC_9) -> 0.0022496593 | Q43: 45779 | R43: 0.030013088 | S43: 0.024734097 | T43: 0.022532491 | U43: 0.024448803 | V43: 0.034216882
J44: HSI | K44: =L43 -> -0.00014803691 | L44: =L39 -> 0.001238853 | M44: =_xlfn.COVARIANCE.S(HSI_9,N225E_9) -> 0.00031522148 | N44: =_xlfn.COVARIANCE.S(HSI_9,STOXX_9) -> 0.00035412126 | O44: =_xlfn.COVARIANCE.S(HSI_9,IXIC_9) -> -8.9646873e-05 | Q44: 45772 | R44: 0.024813865 | S44: 0.02803223 | T44: 0.017356421 | U44: 0.025274763 | V44: 0.067325292
J45: N225E | K45: =M43 -> 0.00080743313 | L45: =M44 -> 0.00031522148 | M45: =M39 -> 0.0010167816 | N45: =_xlfn.COVARIANCE.S(N225E_9,STOXX_9) -> 0.0010225137 | O45: =_xlfn.COVARIANCE.S(N225E_9,IXIC_9) -> 0.0011051865 | Q45: 45765 | R45: -0.026620439 | S45: 0.021864771 | T45: 0.043840533 | U45: 0.043127611 | V45: -0.026189784
J46: STOXX | K46: =N43 -> 0.00088012108 | L46: =N44 -> 0.00035412126 | M46: =N45 -> 0.0010225137 | N46: =N39 -> 0.001084408 | O46: =_xlfn.COVARIANCE.S(STOXX_9,IXIC_9) -> 0.0012616571 | Q46: 45758 | R46: 0.049533001 | S46: -0.082230418 | T46: 0.01769873 | U46: 0.017067294 | V46: 0.072920536
J47: IXIC | K47: =O43 -> 0.0022496593 | L47: =O44 -> -8.9646873e-05 | M47: =O45 -> 0.0011051865 | N47: =O46 -> 0.0012616571 | O47: =O39 -> 0.0033165666 | Q47: 45751 | R47: -0.078613028 | S47: -0.024170147 | T47: -0.071918638 | U47: -0.073603326 | V47: -0.10016747
J49: e | K49: {=TRANSPOSE(K38:O38)} -> 0.0024022485 | Q49: Deviazioni standard | R49: DJIA | S49: HSI | T49: N225 | U49: STOXX | V49: ^IXIC
...

Sheet Ricalcolo
B2: Date | C2: DJIA | D2: HSI | E2: N225E | F2: STOXX | G2: IXIC | K2: DJIA | L2: HSI | M2: N225E | N2: STOXX | O2: IXIC
B3: 45744 | C3: 41583.896 | D3: 3011.98 | E3: 247.78 | F3: 586.93 | G3: 17322.99 | J3: settimana | K3: RENDIMENTI SETTIMANALI
B4: 45751 | C4: 38314.86 | D4: 2939.18 | E4: 229.96 | F4: 543.73 | G4: 15587.79 | J4: 1 | K4: =(C4-C3)/C3 -> -0.078613028 | L4: =(D4-D3)/D3 -> -0.024170147 | M4: =(E4-E3)/E3 -> -0.071918638 | N4: =(F4-F3)/F3 -> -0.073603326 | O4: =(G4-G3)/G3 -> -0.10016747
B5: 45758 | C5: 40212.71 | D5: 2697.49 | E5: 234.03 | F5: 553.01 | G5: 16724.46 | J5: 2 | K5: =(C5-C4)/C4 -> 0.049533001 | L5: =(D5-D4)/D4 -> -0.082230418 | M5: =(E5-E4)/E4 -> 0.01769873 | N5: =(F5-F4)/F4 -> 0.017067294 | O5: =(G5-G4)/G4 -> 0.072920536
B6: 45765 | C6: 39142.23 | D6: 2756.47 | E6: 244.29 | F6: 576.86 | G6: 16286.45 | J6: 3 | K6: =(C6-C5)/C5 -> -0.026620439 | L6: =(D6-D5)/D5 -> 0.021864771 | M6: =(E6-E5)/E5 -> 0.043840533 | N6: =(F6-F5)/F5 -> 0.043127611 | O6: =(G6-G5)/G5 -> -0.026189784
B7: 45772 | C7: 40113.5 | D7: 2833.74 | E7: 248.53 | F7: 591.44 | G7: 17382.94 | J7: 4 | K7: =(C7-C6)/C6 -> 0.024813865 | L7: =(D7-D6)/D6 -> 0.02803223 | M7: =(E7-E6)/E6 -> 0.017356421 | N7: =(F7-F6)/F6 -> 0.025274763 | O7: =(G7-G6)/G6 -> 0.067325292
B8: 45779 | C8: 41317.43 | D8: 2903.83 | E8: 254.13 | F8: 605.9 | G8: 17977.73 | J8: 5 | K8: =(C8-C7)/C7 -> 0.030013088 | L8: =(D8-D7)/D7 -> 0.024734097 | M8: =(E8-E7)/E7 -> 0.022532491 | N8: =(F8-F7)/F7 -> 0.024448803 | O8: =(G8-G7)/G7 -> 0.034216882
B9: 45786 | C9: 41249.38 | D9: 2939.83 | E9: 258.04 | F9: 605.04 | G9: 17928.92 | J9: 6 | K9: =(C9-C8)/C8 -> -0.0016470047 | L9: =(D9-D8)/D8 -> 0.01239742 | M9: =(E9-E8)/E8 -> 0.015385826 | N9: =(F9-F8)/F8 -> -0.0014193761 | O9: =(G9-G8)/G8 -> -0.0027150258
B10: 45793 | C10: 42654.74 | D10: 2987.67 | E10: 259.26 | F10: 613.14 | G10: 19211.1 | J10: 7 | K10: =(C10-C9)/C9 -> 0.034069845 | L10: =(D10-D9)/D9 -> 0.01627305 | M10: =(E10-E9)/E9 -> 0.0047279492 | N10: =(F10-F9)/F9 -> 0.013387545 | O10: =(G10-G9)/G9 -> 0.071514626
B11: 45800 | C11: 41603.07 | D11: 3013.25 | E11: 260.7 | F11: 619.49 | G11: 18737.21 | J11: 8 | K11: =(C11-C10)/C10 -> -0.024655408 | L11: =(D11-D10)/D10 -> 0.0085618559 | M11: =(E11-E10)/E10 -> 0.0055542698 | N11: =(F11-F10)/F10 -> 0.010356525 | O11: =(G11-G10)/G10 -> -0.02466751
B12: 45807 | C12: 42215.73 | D12: 2969.99 | E12: 263.3 | F12: 626.24 | G12: 19175.87 | J12: 9 | K12: =(C12-C11)/C11 -> 0.014726317 | L12: =(D12-D11)/D11 -> -0.014356592 | M12: =(E12-E11)/E11 -> 0.0099731492 | N12: =(F12-F11)/F11 -> 0.01089606 | O12: =(G12-G11)/G11 -> 0.02341117
K13: rendimenti medi
K14: =AVERAGE(K4:K12) -> 0.0024022485 | L14: =AVERAGE(L4:L12) -> -0.00098819268 | M14: =AVERAGE(M4:M12) -> 0.0072389702 | N14: =AVERAGE(N4:N12) -> 0.007726211 | O14: =AVERAGE(O4:O12) -> 0.012849858
B15: Portafogli | C15: DJIA | D15: HSI | E15: N225 | F15: STOXX | G15: ^IXIC | K15: deviazioni standard
B16: 1/N | C16: 0.2 | D16: 0.2 | E16: 0.2 | F16: 0.2 | G16: 0.2 | K16: =_xlfn.STDEV.S(K4:K12) -> 0.039992141 | L16: =_xlfn.STDEV.S(L4:L12) -> 0.035197343 | M16: =_xlfn.STDEV.S(M4:M12) -> 0.031887013 | N16: =_xlfn.STDEV.S(N4:N12) -> 0.032930351 | O16: =_xlfn.STDEV.S(O4:O12) -> 0.05758964
B17: Varianza minima | C17: 0.74039811 | D17: 0.044928717 | E17: -0.00020300168 | F17: 0.23945292 | G17: -0.024576745
B18: Risk party (cov 0) | C18: 0.28097777 | D18: 0.13266384 | E18: 0.16207418 | F18: 0.2338667 | G18: 0.19041751
B19: Tangente | C19: 0.47234224 | D19: 0.051004806 | E19: -0.25520379 | F19: -0.012351426 | G19: 0.74420817
K21: RENDIMENTI SETTIMANALI PORTAFOGLI
B22: Portafogli | C22: pesi approssimati | K22: 1 | L22: 2 | M22: 3 | N22: 4 | O22: 5 | P22: 6 | Q22: 7 | R22: 8 | S22: 9
B23: 1/N | C23: 0.2 | D23: 0.2 | E23: 0.2 | F23: 0.2 | G23: 0.2 | J23: w_EW | K23: {=MMULT(C23:G26,TRANSPOSE(K4:O12))} -> -0.069694521 | L23: 0.014997829 | M23: 0.011204538 | N23: 0.032560514 | O23: 0.027189072 | P23: 0.0044003679 | Q23: 0.027994603 | R23: -0.0049700533 | S23: 0.0089300208
B24: Varianza minima | C24: 0.74 | D24: 0.04 | E24: 0 | F24: 0.24 | G24: -0.02 | J24: w_MVP | K24: -0.074801896 | L24: 0.036002944 | M24: -0.0079501119 | N24: 0.024202986 | O24: 0.028382424 | P24: -0.0010092364 | Q24: 0.027645326 | R24: -0.014923611 | S24: 0.012470042
B25: Risk party (cov 0) | C25: 0.28 | D25: 0.13 | E25: 0.16 | F25: 0.23 | G25: 0.19 | J25: w_RP | K25: -0.072621332 | L25: 0.023791462 | M25: 0.007346474 | N25: 0.0319741 | O25: 0.027348728 | P25: 0.0027699241 | Q25: 0.029078439 | R25: -0.0072066157 | S25: 0.010806932
B26: Tangente | C26: 0.47 | D26: 0.05 | E26: -0.26 | F26: -0.01 | G26: 0.74 | J26: w_T | K26: -0.092845676 | L26: 0.068357843 | M26: -0.042628623 | N26: 0.058119427 | O26: 0.034560413 | P26: -0.0061494613 | Q26: 0.068384161 | R26: -0.030961582 | S26: 0.020825826
K29: rendim medi | L29: rendim medi % | M29: varianza | N29: dev standard | O29: sharpe ratio
B30: tasso annuale | D30: 0.02 | J30: w_EW | K30: =AVERAGE(K23:S23)+1 -> 1.0058458 | L30: =AVERAGE(K23:S23) -> 0.0058458189 | M30: =_xlfn.VAR.S(K23:S23) -> 0.0009508976 | N30: =_xlfn.STDEV.S(K23:S23) -> 0.030836628 | O30: =(K30-D$31)/N30 -> 0.17722193 | Q30: 1.0058458 | R30: 0.0058458189 | S30: 0.0009508976 | T30: 0.030836628 | U30: 0.17722193
B31: tasso settimanale | D31: =((1+D30)^(1/52)) -> 1.0003809 | J31: w_MVP | K31: =AVERAGE(K24:S24)+1 -> 1.0033354 | L31: =AVERAGE(K24:S24) -> 0.0033354297 | M31: =_xlfn.VAR.S(K24:S24) -> 0.0011736824 | N31: =_xlfn.STDEV.S(K24:S24) -> 0.034259049 | O31: =(K31-D$31)/N31 -> 0.086241081 | Q31: 1.0033354 | R31: 0.0033354297 | S31: 0.0011736824 | T31: 0.034259049 | U31: 0.086241081
J32: w_RP | K32: =AVERAGE(K25:S25)+1 -> 1.0059209 | L32: =AVERAGE(K25:S25) -> 0.0059209013 | M32: =_xlfn.VAR.S(K25:S25) -> 0.0010463247 | N32: =_xlfn.STDEV.S(K25:S25) -> 0.032346943 | O32: =(K32-D$31)/N32 -> 0.17126839 | Q32: 1.0059209 | R32: 0.0059209013 | S32: 0.0010463247 | T32: 0.032346943 | U32: 0.17126839
J33: w_T | K33: =AVERAGE(K26:S26)+1 -> 1.0086291 | L33: =AVERAGE(K26:S26) -> 0.0086291475 | M33: =_xlfn.VAR.S(K26:S26) -> 0.0031398735 | N33: =_xlfn.STDEV.S(K26:S26) -> 0.056034574 | O33: =(K33-D$31)/N33 -> 0.14719939 | Q33: 1.0086291 | R33: 0.0086291475 | S33: 0.0031398735 | T33: 0.056034574 | U33: 0.14719939
K36: -0.069694521 | L36: 0.014997829 | M36: 0.011204538 | N36: 0.032560514 | O36: 0.027189072 | P36: 0.0044003679 | Q36: 0.027994603 | R36: -0.0049700533 | S36: 0.0089300208
K37: -0.074801896 | L37: 0.036002944 | M37: -0.0079501119 | N37: 0.024202986 | O37: 0.028382424 | P37: -0.0010092364 | Q37: 0.027645326 | R37: -0.014923611 | S37: 0.012470042
K38: -0.072621332 | L38: 0.023791462 | M38: 0.007346474 | N38: 0.0319741 | O38: 0.027348728 | P38: 0.0027699241 | Q38: 0.029078439 | R38: -0.0072066157 | S38: 0.010806932
K39: -0.092845676 | L39: 0.068357843 | M39: -0.042628623 | N39: 0.058119427 | O39: 0.034560413 | P39: -0.0061494613 | Q39: 0.068384161 | R39: -0.030961582 | S39: 0.020825826
