Workbook

Sheet Historical_Simulation
A1: =_xll.Thomson.Reuters.AFOSpreadsheetFormulas.DSGRID("@AAPL,@AMZN,@FB"," ","-5Y","","D","RowHeader=true;ColHeader=true;Heading=true;LatestFirstValue=true;DispSeriesDescription=false;YearlyTSFormat=false;QuarterlyTSFormat=false","") -> 0 | B1: 42283
A2: End | B2: 44110
A3: Frequency | B3: D
A4: Name | B4: APPLE | C4: AMAZON | D4: FACEBOOK CLASS A | E4: Portfolio Value [50 2 -20] | F4: GAIN | G4: LOSS
A5: 44110 | B5: 113.16 | C5: 3099.96 | D5: 258.6599 | E5: =50*B5+2*C5-20*D5 -> 6684.722 | F5: =E5-E6 -> -245.68 | G5: =-F5 -> 245.68
A6: 44109 | B6: 116.5 | C6: 3199.2 | D6: 264.6499 | E6: =50*B6+2*C6-20*D6 -> 6930.402 | F6: =E6-E7 -> 228.2 | G6: =-F6 -> -228.2 | I6: Probability Loss is greater than
A7: 44106 | B7: 113.02 | C7: 3125 | D7: 259.9399 | E7: =50*B7+2*C7-20*D7 -> 6702.202 | F7: =E7-E8 -> -247.22 | G7: =-F7 -> 247.22 | I7: 0 | J7: =COUNTIF($G$5:$G$1304,">"&I7)/1299 -> 0.46959199
A8: 44105 | B8: 116.79 | C8: 3221.26 | D8: 266.6299 | E8: =50*B8+2*C8-20*D8 -> 6949.422 | F8: =E8-E9 -> 99.46 | G8: =-F8 -> -99.46 | I8: 10 | J8: =COUNTIF($G$5:$G$1304,">"&I8)/1299 -> 0.34026174
A9: 44104 | B9: 115.81 | C9: 3148.73 | D9: 261.8999 | E9: =50*B9+2*C9-20*D9 -> 6849.962 | F9: =E9-E10 -> 91.502 | G9: =-F9 -> -91.502 | I9: 20 | J9: =COUNTIF($G$5:$G$1304,">"&I9)/1299 -> 0.26712856
A10: 44103 | B10: 114.09 | C10: 3144.88 | D10: 261.79 | E10: =50*B10+2*C10-20*D10 -> 6758.46 | F10: =E10-E11 -> -201.238 | G10: =-F10 -> 201.238 | I10: 30 | J10: =COUNTIF($G$5:$G$1304,">"&I10)/1299 -> 0.2047729
A11: 44102 | B11: 114.96 | C11: 3174.05 | D11: 256.8201 | E11: =50*B11+2*C11-20*D11 -> 6959.698 | F11: =E11-E12 -> 251.838 | G11: =-F11 -> -251.838 | I11: 40 | J11: =COUNTIF($G$5:$G$1304,">"&I11)/1299 -> 0.16551193
A12: 44099 | B12: 112.28 | C12: 3095.13 | D12: 254.82 | E12: =50*B12+2*C12-20*D12 -> 6707.86 | F12: =E12-E13 -> 247.88 | G12: =-F12 -> -247.88 | I12: 50 | J12: =COUNTIF($G$5:$G$1304,">"&I12)/1299 -> 0.13163972
A13: 44098 | B13: 108.22 | C13: 3019.79 | D13: 249.53 | E13: =50*B13+2*C13-20*D13 -> 6459.98 | F13: =E13-E14 -> 84.66 | G13: =-F13 -> -84.66 | I13: 60 | J13: =COUNTIF($G$5:$G$1304,">"&I13)/1299 -> 0.10777521
A14: 44097 | B14: 107.12 | C14: 2999.86 | D14: 249.02 | E14: =50*B14+2*C14-20*D14 -> 6375.32 | F14: =E14-E15 -> -378.16 | G14: =-F14 -> 378.16 | I14: 70 | J14: =COUNTIF($G$5:$G$1304,">"&I14)/1299 -> 0.095458045
A15: 44096 | B15: 111.81 | C15: 3128.99 | D15: 254.75 | E15: =50*B15+2*C15-20*D15 -> 6753.48 | F15: =E15-E16 -> 291.54 | G15: =-F15 -> -291.54 | I15: 80 | J15: =COUNTIF($G$5:$G$1304,">"&I15)/1299 -> 0.089299461
A16: 44095 | B16: 110.08 | C16: 2960.47 | D16: 248.15 | E16: =50*B16+2*C16-20*D16 -> 6461.94 | F16: =E16-E17 -> 260.72 | G16: =-F16 -> -260.72 | I16: 90 | J16: =COUNTIF($G$5:$G$1304,">"&I16)/1299 -> 0.073903002 | M16: VaR 95% | N16: =I20 -> 112
A17: 44092 | B17: 106.84 | C17: 2954.91 | D17: 252.53 | E17: =50*B17+2*C17-20*D17 -> 6201.22 | F17: =E17-E18 -> -236.84 | G17: =-F17 -> 236.84 | I17: 100 | J17: =COUNTIF($G$5:$G$1304,">"&I17)/1299 -> 0.061585835 | M17: VaR 99% | N17: =I42 -> 242
A18: 44091 | B18: 110.34 | C18: 3008.73 | D18: 254.82 | E18: =50*B18+2*C18-20*D18 -> 6438.06 | F18: =E18-E19 -> -54.24 | G18: =-F18 -> 54.24 | I18: 110 | J18: =COUNTIF($G$5:$G$1304,">"&I18)/1299 -> 0.05234796
A19: 44090 | B19: 112.13 | C19: 3078.1 | D19: 263.52 | E19: =50*B19+2*C19-20*D19 -> 6492.3 | F19: =E19-E20 -> -148.562 | G19: =-F19 -> 148.562 | I19: 111 | J19: =COUNTIF($G$5:$G$1304,">"&I19)/1299 -> 0.050808314
A20: 44089 | B20: 115.54 | C20: 3156.13 | D20: 272.4199 | E20: =50*B20+2*C20-20*D20 -> 6640.862 | F20: =E20-E21 -> -9.83 | G20: =-F20 -> 9.83 | I20: 112 | J20: =COUNTIF($G$5:$G$1304,">"&I20)/1299 -> 0.050038491
A21: 44088 | B21: 115.355 | C21: 3102.97 | D21: 266.1499 | E21: =50*B21+2*C21-20*D21 -> 6650.692 | F21: =E21-E22 -> 150.454 | G21: =-F21 -> -150.454 | I21: 113 | J21: =COUNTIF($G$5:$G$1304,">"&I21)/1299 -> 0.050038491
A22: 44085 | B22: 112 | C22: 3116.22 | D22: 266.6101 | E22: =50*B22+2*C22-20*D22 -> 6500.238 | F22: =E22-E23 -> -162.68 | G22: =-F22 -> 162.68 | I22: 114 | J22: =COUNTIF($G$5:$G$1304,">"&I22)/1299 -> 0.049268668
A23: 44084 | B23: 113.49 | C23: 3175.11 | D23: 268.0901 | E23: =50*B23+2*C23-20*D23 -> 6662.918 | F23: =E23-E24 -> -265.902 | G23: =-F23 -> 265.902 | I23: 115 | J23: =COUNTIF($G$5:$G$1304,">"&I23)/1299 -> 0.048498845
A24: 44083 | B24: 117.32 | C24: 3268.61 | D24: 273.72 | E24: =50*B24+2*C24-20*D24 -> 6928.82 | F24: =E24-E25 -> 411.338 | G24: =-F24 -> -411.338 | I24: 116 | J24: =COUNTIF($G$5:$G$1304,">"&I24)/1299 -> 0.047729022
A25: 44082 | B25: 112.82 | C25: 3149.84 | D25: 271.1599 | E25: =50*B25+2*C25-20*D25 -> 6517.482 | F25: =E25-E26 -> -465.158 | G25: =-F25 -> 465.158 | I25: 117 | J25: =COUNTIF($G$5:$G$1304,">"&I25)/1299 -> 0.046959199
A26: 44078 | B26: 120.96 | C26: 3294.62 | D26: 282.73 | E26: =50*B26+2*C26-20*D26 -> 6982.64 | F26: =E26-E27 -> 25.042 | G26: =-F26 -> -25.042 | I26: 118 | J26: =COUNTIF($G$5:$G$1304,">"&I26)/1299 -> 0.046959199
A27: 44077 | B27: 120.88 | C27: 3368 | D27: 291.1201 | E27: =50*B27+2*C27-20*D27 -> 6957.598 | F27: =E27-E28 -> -625.302 | G27: =-F27 -> 625.302 | I27: 119 | J27: =COUNTIF($G$5:$G$1304,">"&I27)/1299 -> 0.046189376
A28: 44076 | B28: 131.4 | C28: 3531.45 | D28: 302.5 | E28: =50*B28+2*C28-20*D28 -> 7582.9 | F28: =E28-E29 -> -215.542 | G28: =-F28 -> 215.542 | I28: 120 | J28: =COUNTIF($G$5:$G$1304,">"&I28)/1299 -> 0.046189376
A29: 44075 | B29: 134.18 | C29: 3499.12 | D29: 295.4399 | E29: =50*B29+2*C29-20*D29 -> 7798.442 | F29: =E29-E30 -> 308.522 | G29: =-F29 -> -308.522 | I29: 130 | J29: =COUNTIF($G$5:$G$1304,">"&I29)/1299 -> 0.040030793
... A52: 44042 | B52: 96.19 | C52: 3051.88 | D52: 234.5 | E52: =50*B52+2*C52-20*D52 -> 6223.26 | F52: =E52-E53 -> 70 | G52: =-F52 -> -70 | I52: 270 | J52: =COUNTIF($G$5:$G$1304,">"&I52)/1299 -> 0.0061585835
A53: 44041 | B53: 95.04 | C53: 3033.53 | D53: 233.29 | E53: =50*B53+2*C53-20*D53 -> 6153.26 | F53: =E53-E54 -> 92.375 | G53: =-F53 -> -92.375
A54: 44040 | B54: 93.2525 | C54: 3000.33 | D54: 230.12 | E54: =50*B54+2*C54-20*D54 -> 6060.885 | F54: =E54-E55 -> -120.035 | G54: =-F54 -> 120.035
A55: 44039 | B55: 94.81 | C55: 3055.21 | D55: 233.5 | E55: =50*B55+2*C55-20*D55 -> 6180.92 | F55: =E55-E56 -> 146.55 | G55: =-F55 -> -146.55
A56: 44036 | B56: 92.615 | C56: 3008.91 | D56: 230.71 | E56: =50*B56+2*C56-20*D56 -> 6034.37 | F56: =E56-E57 -> 71.02 | G56: =-F56 -> -71.02
A57: 44035 | B57: 92.845 | C57: 2986.55 | D57: 232.6 | E57: =50*B57+2*C57-20*D57 -> 5963.35 | F57: =E57-E58 -> -302.695 | G57: =-F57 -> 302.695
A58: 44034 | B58: 97.2725 | C58: 3099.91 | D58: 239.87 | E58: =50*B58+2*C58-20*D58 -> 6266.045 | F58: =E58-E59 -> -25.535 | G58: =-F58 -> 25.535
A59: 44033 | B59: 97 | C59: 3138.29 | D59: 241.75 | E59: =50*B59+2*C59-20*D59 -> 6291.58 | F59: =E59-E60 -> -111.575 | G59: =-F59 -> 111.575
A60: 44032 | B60: 98.3575 | C60: 3196.84 | D60: 245.42 | E60: =50*B60+2*C60-20*D60 -> 6403.155 | F60: =E60-E61 -> 503.44 | G60: =-F60 -> -503.44
A61: 44029 | B61: 96.3275 | C61: 2961.97 | D61: 242.03 | E61: =50*B61+2*C61-20*D61 -> 5899.715 | F61: =E61-E62 -> -107.61 | G61: =-F61 -> 107.61
A62: 44028 | B62: 96.5225 | C62: 2999.9 | D62: 240.93 | E62: =50*B62+2*C62-20*D62 -> 6007.325 | F62: =E62-E63 -> -91.065 | G62: =-F62 -> 91.065
...

Sheet Calcolo portafogli
C1: APPLE | E1: AMAZON | G1: FACEBOOK | J1: Apple e Amazon | Q1: Apple e Amazon | X1: Apple e Facebook | AE1: Apple e Facebook
C2: Loss | E2: Loss | G2: Loss
J3: a= | K3: 0.46058623 | M3: p= | N3: 0.05 | Q3: a= | R3: 0.63025052 | T3: p= | U3: 0.01 | X3: a= | Y3: -4.6030638 | AA3: p= | AB3: 0.05 | AE3: a= | AF3: -2.9060611 | AH3: p= | AI3: 0.01
A4: {=J6:J1304} -> 44110 | C4: =-(Historical_Simulation!B5-Historical_Simulation!B6) -> 3.34 | E4: =-(Historical_Simulation!C5-Historical_Simulation!C6) -> 99.24 | G4: =-(Historical_Simulation!D5-Historical_Simulation!D6) -> 5.99
A5: 44109 | C5: =-(Historical_Simulation!B6-Historical_Simulation!B7) -> -3.48 | E5: =-(Historical_Simulation!C6-Historical_Simulation!C7) -> -74.2 | G5: =-(Historical_Simulation!D6-Historical_Simulation!D7) -> -4.71 | K5: Loss | M5: Loss media= | N5: =AVERAGE(K6:K1304) -> -1.0943341 | R5: Loss | T5: Loss media= | U5: =AVERAGE(R6:R1304) -> -0.77079022 | Y5: Loss | AA5: Loss media= | AB5: =AVERAGE(Y6:Y1304) -> -0.41303515 | AF5: Loss | AH5: Loss media= | AI5: =AVERAGE(AF6:AF1304) -> -0.30783483
A6: 44106 | C6: =-(Historical_Simulation!B7-Historical_Simulation!B8) -> 3.77 | E6: =-(Historical_Simulation!C7-Historical_Simulation!C8) -> 96.26 | G6: =-(Historical_Simulation!D7-Historical_Simulation!D8) -> 6.69 | J6: {=Historical_Simulation!A5:A1303} -> 44110 | K6: =C4*$K$3+E4*(1-$K$3) -> 55.069781 | Q6: {=Historical_Simulation!A5:A1303} -> 44110 | R6: =C4*$R$3+E4*(1-$R$3) -> 38.798975 | X6: {=Historical_Simulation!A5:A1303} -> 44110 | Y6: =C4*$Y$3+G4*(1-$Y$3) -> 18.188119 | AE6: {=Historical_Simulation!A5:A1303} -> 44110 | AF6: =C4*$AF$3+G4*(1-$AF$3) -> 13.691062 | AM6: portafogli | AN6: p | AO6: Azioni Apple | AP6: Azioni Amazon | AQ6: Azioni Facebook
A7: 44105 | C7: =-(Historical_Simulation!B8-Historical_Simulation!B9) -> -0.98 | E7: =-(Historical_Simulation!C8-Historical_Simulation!C9) -> -72.53 | G7: =-(Historical_Simulation!D8-Historical_Simulation!D9) -> -4.73 | J7: 44109 | K7: =C5*$K$3+E5*(1-$K$3) -> -41.627342 | M7: Loss dev.std= | N7: =_xlfn.STDEV.S(K6:K1304) -> 17.688218 | Q7: 44109 | R7: =C5*$R$3+E5*(1-$R$3) -> -29.628683 | T7: Loss dev.std= | U7: =_xlfn.STDEV.S(R6:R1304) -> 12.367364 | X7: 44109 | Y7: =C5*$Y$3+G5*(1-$Y$3) -> -10.371768 | AA7: Loss dev.std= | AB7: =_xlfn.STDEV.S(Y6:Y1304) -> 17.27385 | AE7: 44109 | AF7: =C5*$AF$3+G5*(1-$AF$3) -> -8.2844552 | AH7: Loss dev.std= | AI7: =_xlfn.STDEV.S(AF6:AF1304) -> 12.168359 | AM7: 1 | AN7: 0.05 | AO7: =K3 -> 0.46058623 | AP7: =1-AO7 -> 0.53941377
A8: 44104 | C8: =-(Historical_Simulation!B9-Historical_Simulation!B10) -> -1.72 | E8: =-(Historical_Simulation!C9-Historical_Simulation!C10) -> -3.85 | G8: =-(Historical_Simulation!D9-Historical_Simulation!D10) -> -0.1099 | J8: 44106 | K8: =C6*$K$3+E6*(1-$K$3) -> 53.66038 | Q8: 44106 | R8: =C6*$R$3+E6*(1-$R$3) -> 37.968129 | X8: 44106 | Y8: =C6*$Y$3+G6*(1-$Y$3) -> 20.130946 | AE8: 44106 | AF8: =C6*$AF$3+G6*(1-$AF$3) -> 15.175698 | AM8: 2 | AN8: 0.01 | AO8: =R3 -> 0.63025052 | AP8: =1-AO8 -> 0.36974948
A9: 44103 | C9: =-(Historical_Simulation!B10-Historical_Simulation!B11) -> 0.87 | E9: =-(Historical_Simulation!C10-Historical_Simulation!C11) -> 29.17 | G9: =-(Historical_Simulation!D10-Historical_Simulation!D11) -> -4.9699 | J9: 44105 | K9: =C7*$K$3+E7*(1-$K$3) -> -39.575055 | M9: VaR= | N9: =N5+N7*NORMSINV(1-N3) -> 28.000195 | Q9: 44105 | R9: =C7*$R$3+E7*(1-$R$3) -> -27.435575 | T9: VaR= | U9: =U5+U7*NORMSINV(1-U3) -> 28 | X9: 44105 | Y9: =C7*$Y$3+G7*(1-$Y$3) -> -21.991489 | AA9: VaR= | AB9: =AB5+AB7*NORMSINV(1-AB3) -> 27.999919 | AE9: 44105 | AF9: =C7*$AF$3+G7*(1-$AF$3) -> -15.627729 | AH9: VaR= | AI9: =AI5+AI7*NORMSINV(1-AI3) -> 28 | AM9: 3 | AN9: 0.05 | AO9: =Y3 -> -4.6030638 | AQ9: =1-AO9 -> 5.6030638
A10: 44102 | C10: =-(Historical_Simulation!B11-Historical_Simulation!B12) -> -2.68 | E10: =-(Historical_Simulation!C11-Historical_Simulation!C12) -> -78.92 | G10: =-(Historical_Simulation!D11-Historical_Simulation!D12) -> -2.0001 | J10: 44104 | K10: =C8*$K$3+E8*(1-$K$3) -> -2.8689513 | Q10: 44104 | R10: =C8*$R$3+E8*(1-$R$3) -> -2.5075664 | X10: 44104 | Y10: =C8*$Y$3+G8*(1-$Y$3) -> 7.3014931 | AE10: 44104 | AF10: =C8*$AF$3+G8*(1-$AF$3) -> 4.569149 | AM10: 4 | AN10: 0.01 | AO10: =AF3 -> -2.9060611 | AQ10: =1-AO10 -> 3.9060611
A11: 44099 | C11: =-(Historical_Simulation!B12-Historical_Simulation!B13) -> -4.06 | E11: =-(Historical_Simulation!C12-Historical_Simulation!C13) -> -75.34 | G11: =-(Historical_Simulation!D12-Historical_Simulation!D13) -> -5.29 | J11: 44103 | K11: =C9*$K$3+E9*(1-$K$3) -> 16.13541 | M11: ES= | N11: =N5+N7/SQRT(2*PI())*EXP(-(NORMSINV(1-N3)^2)/2)/N3 -> 35.391379 | Q11: 44103 | R11: =C9*$R$3+E9*(1-$R$3) -> 11.33391 | T11: ES= | U11: =U5+U7/SQRT(2*PI())*EXP(-(NORMSINV(1-U3)^2)/2)/U3 -> 32.190884 | X11: 44103 | Y11: =C9*$Y$3+G9*(1-$Y$3) -> -31.851332 | AA11: ES= | AB11: =AB5+AB7/SQRT(2*PI())*EXP(-(NORMSINV(1-AB3)^2)/2)/AB3 -> 35.217956 | AE11: 44103 | AF11: =C9*$AF$3+G9*(1-$AF$3) -> -21.941006 | AH11: ES= | AI11: =AI5+AI7/SQRT(2*PI())*EXP(-(NORMSINV(1-AI3)^2)/2)/AI3 -> 32.123448
A12: 44098 | C12: =-(Historical_Simulation!B13-Historical_Simulation!B14) -> -1.1 | E12: =-(Historical_Simulation!C13-Historical_Simulation!C14) -> -19.93 | G12: =-(Historical_Simulation!D13-Historical_Simulation!D14) -> -0.51 | J12: 44102 | K12: =C10*$K$3+E10*(1-$K$3) -> -43.804906 | Q12: 44102 | R12: =C10*$R$3+E10*(1-$R$3) -> -30.8697 | X12: 44102 | Y12: =C10*$Y$3+G10*(1-$Y$3) -> 1.1295231 | AE12: 44102 | AF12: =C10*$AF$3+G10*(1-$AF$3) -> -0.024269052 | AM12: portafogli | AN12: ES5% | AO12: ES1%
A13: 44097 | C13: =-(Historical_Simulation!B14-Historical_Simulation!B15) -> 4.69 | E13: =-(Historical_Simulation!C14-Historical_Simulation!C15) -> 129.13 | G13: =-(Historical_Simulation!D14-Historical_Simulation!D15) -> 5.73 | J13: 44099 | K13: =C11*$K$3+E11*(1-$K$3) -> -42.509414 | Q13: 44099 | R13: =C11*$R$3+E11*(1-$R$3) -> -30.415743 | X13: 44099 | Y13: =C11*$Y$3+G11*(1-$Y$3) -> -10.951768 | AE13: 44099 | AF13: =C11*$AF$3+G11*(1-$AF$3) -> -8.8644552 | AM13: 1 | AN13: =N11 -> 35.391379 | AO13: =N5+N7/SQRT(2*PI())*EXP(-(NORMSINV(1-0.01)^2)/2)/0.01 -> 46.048555
A14: 44096 | C14: =-(Historical_Simulation!B15-Historical_Simulation!B16) -> -1.73 | E14: =-(Historical_Simulation!C15-Historical_Simulation!C16) -> -168.52 | G14: =-(Historical_Simulation!D15-Historical_Simulation!D16) -> -6.6 | J14: 44098 | K14: =C12*$K$3+E12*(1-$K$3) -> -11.257161 | Q14: 44098 | R14: =C12*$R$3+E12*(1-$R$3) -> -8.0623826 | X14: 44098 | Y14: =C12*$Y$3+G12*(1-$Y$3) -> 2.2058077 | AE14: 44098 | AF14: =C12*$AF$3+G12*(1-$AF$3) -> 1.2045761 | AM14: 2 | AN14: =U5+U7/SQRT(2*PI())*EXP(-(NORMSINV(1-0.05)^2)/2)/0.05 -> 24.739529 | AO14: =U11 -> 32.190884
A15: 44095 | C15: =-(Historical_Simulation!B16-Historical_Simulation!B17) -> -3.24 | E15: =-(Historical_Simulation!C16-Historical_Simulation!C17) -> -5.56 | G15: =-(Historical_Simulation!D16-Historical_Simulation!D17) -> 4.38 | J15: 44097 | K15: =C13*$K$3+E13*(1-$K$3) -> 71.81465 | Q15: 44097 | R15: =C13*$R$3+E13*(1-$R$3) -> 50.701625 | X15: 44097 | Y15: =C13*$Y$3+G13*(1-$Y$3) -> 10.517186 | AE15: 44097 | AF15: =C13*$AF$3+G13*(1-$AF$3) -> 8.7523036 | AM15: 3 | AN15: =AB11 -> 35.217956 | AO15: =AB5+AB7/SQRT(2*PI())*EXP(-(NORMSINV(1-0.01)^2)/2)/0.01 -> 45.625475
A16: 44092 | C16: =-(Historical_Simulation!B17-Historical_Simulation!B18) -> 3.5 | E16: =-(Historical_Simulation!C17-Historical_Simulation!C18) -> 53.82 | G16: =-(Historical_Simulation!D17-Historical_Simulation!D18) -> 2.29 | J16: 44096 | K16: =C14*$K$3+E14*(1-$K$3) -> -91.698823 | Q16: 44096 | R16: =C14*$R$3+E14*(1-$R$3) -> -63.400515 | X16: 44096 | Y16: =C14*$Y$3+G14*(1-$Y$3) -> -29.016921 | AE16: 44096 | AF16: =C14*$AF$3+G14*(1-$AF$3) -> -20.752518 | AM16: 4 | AN16: =AI5+AI7/SQRT(2*PI())*EXP(-(NORMSINV(1-0.05)^2)/2)/0.05 -> 24.791994 | AO16: =AI11 -> 32.123448
A17: 44091 | C17: =-(Historical_Simulation!B18-Historical_Simulation!B19) -> 1.79 | E17: =-(Historical_Simulation!C18-Historical_Simulation!C19) -> 69.37 | G17: =-(Historical_Simulation!D18-Historical_Simulation!D19) -> 8.7 | J17: 44095 | K17: =C15*$K$3+E15*(1-$K$3) -> -4.4914399 | Q17: 44095 | R17: =C15*$R$3+E15*(1-$R$3) -> -4.0978188 | X17: 44095 | Y17: =C15*$Y$3+G15*(1-$Y$3) -> 39.455346 | AE17: 44095 | AF17: =C15*$AF$3+G15*(1-$AF$3) -> 26.524186
A18: 44090 | C18: =-(Historical_Simulation!B19-Historical_Simulation!B20) -> 3.41 | E18: =-(Historical_Simulation!C19-Historical_Simulation!C20) -> 78.03 | G18: =-(Historical_Simulation!D19-Historical_Simulation!D20) -> 8.8999 | J18: 44092 | K18: =C16*$K$3+E16*(1-$K$3) -> 30.643301 | Q18: 44092 | R18: =C16*$R$3+E16*(1-$R$3) -> 22.105794 | X18: 44092 | Y18: =C16*$Y$3+G16*(1-$Y$3) -> -3.2797072 | AE18: 44092 | AF18: =C16*$AF$3+G16*(1-$AF$3) -> -1.2263339
A19: 44089 | C19: =-(Historical_Simulation!B20-Historical_Simulation!B21) -> -0.185 | E19: =-(Historical_Simulation!C20-Historical_Simulation!C21) -> -53.16 | G19: =-(Historical_Simulation!D20-Historical_Simulation!D21) -> -6.27 | J19: 44091 | K19: =C17*$K$3+E17*(1-$K$3) -> 38.243583 | Q19: 44091 | R19: =C17*$R$3+E17*(1-$R$3) -> 26.77767 | X19: 44091 | Y19: =C17*$Y$3+G17*(1-$Y$3) -> 40.507171 | AE19: 44091 | AF19: =C17*$AF$3+G17*(1-$AF$3) -> 28.780882
A20: 44088 | C20: =-(Historical_Simulation!B21-Historical_Simulation!B22) -> -3.355 | E20: =-(Historical_Simulation!C21-Historical_Simulation!C22) -> 13.25 | G20: =-(Historical_Simulation!D21-Historical_Simulation!D22) -> 0.4602 | J20: 44090 | K20: =C18*$K$3+E18*(1-$K$3) -> 43.661056 | Q20: 44090 | R20: =C18*$R$3+E18*(1-$R$3) -> 31.000706 | X20: 44090 | Y20: =C18*$Y$3+G18*(1-$Y$3) -> 34.17026 | AE20: 44090 | AF20: =C18*$AF$3+G18*(1-$AF$3) -> 24.853885
A21: 44085 | C21: =-(Historical_Simulation!B22-Historical_Simulation!B23) -> 1.49 | E21: =-(Historical_Simulation!C22-Historical_Simulation!C23) -> 58.89 | G21: =-(Historical_Simulation!D22-Historical_Simulation!D23) -> 1.48 | J21: 44089 | K21: =C19*$K$3+E19*(1-$K$3) -> -28.760444 | Q21: 44089 | R21: =C19*$R$3+E19*(1-$R$3) -> -19.772478 | X21: 44089 | Y21: =C19*$Y$3+G19*(1-$Y$3) -> -34.279643 | AE21: 44089 | AF21: =C19*$AF$3+G19*(1-$AF$3) -> -23.953382
A22: 44084 | C22: =-(Historical_Simulation!B23-Historical_Simulation!B24) -> 3.83 | E22: =-(Historical_Simulation!C23-Historical_Simulation!C24) -> 93.5 | G22: =-(Historical_Simulation!D23-Historical_Simulation!D24) -> 5.6299 | J22: 44088 | K22: =C20*$K$3+E20*(1-$K$3) -> 5.6019657 | Q22: 44088 | R22: =C20*$R$3+E20*(1-$R$3) -> 2.78469 | X22: 44088 | Y22: =C20*$Y$3+G20*(1-$Y$3) -> 18.021809 | AE22: 44088 | AF22: =C20*$AF$3+G20*(1-$AF$3) -> 11.547404
A23: 44083 | C23: =-(Historical_Simulation!B24-Historical_Simulation!B25) -> -4.5 | E23: =-(Historical_Simulation!C24-Historical_Simulation!C25) -> -118.77 | G23: =-(Historical_Simulation!D24-Historical_Simulation!D25) -> -2.5601 | J23: 44085 | K23: =C21*$K$3+E21*(1-$K$3) -> 32.45235 | Q23: 44085 | R23: =C21*$R$3+E21*(1-$R$3) -> 22.71362 | X23: 44085 | Y23: =C21*$Y$3+G21*(1-$Y$3) -> 1.4339694 | AE23: 44085 | AF23: =C21*$AF$3+G21*(1-$AF$3) -> 1.4509394
A24: 44082 | C24: =-(Historical_Simulation!B25-Historical_Simulation!B26) -> 8.14 | E24: =-(Historical_Simulation!C25-Historical_Simulation!C26) -> 144.78 | G24: =-(Historical_Simulation!D25-Historical_Simulation!D26) -> 11.5701 | J24: 44084 | K24: =C22*$K$3+E22*(1-$K$3) -> 52.199233 | Q24: 44084 | R24: =C22*$R$3+E22*(1-$R$3) -> 36.985435 | X24: 44084 | Y24: =C22*$Y$3+G22*(1-$Y$3) -> 13.914955 | AE24: 44084 | AF24: =C22*$AF$3+G22*(1-$AF$3) -> 10.860519
A25: 44078 | C25: =-(Historical_Simulation!B26-Historical_Simulation!B27) -> -0.08 | E25: =-(Historical_Simulation!C26-Historical_Simulation!C27) -> 73.38 | G25: =-(Historical_Simulation!D26-Historical_Simulation!D27) -> 8.3901 | J25: 44083 | K25: =C23*$K$3+E23*(1-$K$3) -> -66.138812 | Q25: 44083 | R25: =C23*$R$3+E23*(1-$R$3) -> -46.751273 | X25: 44083 | Y25: =C23*$Y$3+G23*(1-$Y$3) -> 6.3693835 | AE25: 44083 | AF25: =C23*$AF$3+G23*(1-$AF$3) -> 3.0773679
A26: 44077 | C26: =-(Historical_Simulation!B27-Historical_Simulation!B28) -> 10.52 | E26: =-(Historical_Simulation!C27-Historical_Simulation!C28) -> 163.45 | G26: =-(Historical_Simulation!D27-Historical_Simulation!D28) -> 11.3799 | J26: 44082 | K26: =C24*$K$3+E24*(1-$K$3) -> 81.845498 | Q26: 44082 | R26: =C24*$R$3+E24*(1-$R$3) -> 58.662568 | X26: 44082 | Y26: =C24*$Y$3+G24*(1-$Y$3) -> 27.359069 | AE26: 44082 | AF26: =C24*$AF$3+G24*(1-$AF$3) -> 21.53818
A27: 44076 | C27: =-(Historical_Simulation!B28-Historical_Simulation!B29) -> 2.78 | E27: =-(Historical_Simulation!C28-Historical_Simulation!C29) -> -32.33 | G27: =-(Historical_Simulation!D28-Historical_Simulation!D29) -> -7.0601 | J27: 44078 | K27: =C25*$K$3+E25*(1-$K$3) -> 39.545336 | Q27: 44078 | R27: =C25*$R$3+E25*(1-$R$3) -> 27.081796 | X27: 44078 | Y27: =C25*$Y$3+G25*(1-$Y$3) -> 47.378511 | AE27: 44078 | AF27: =C25*$AF$3+G25*(1-$AF$3) -> 33.004728
A28: 44075 | C28: =-(Historical_Simulation!B29-Historical_Simulation!B30) -> -5.14 | E28: =-(Historical_Simulation!C29-Historical_Simulation!C30) -> -48.16 | G28: =-(Historical_Simulation!D29-Historical_Simulation!D30) -> -2.2399 | J28: 44077 | K28: =C26*$K$3+E26*(1-$K$3) -> 93.012548 | Q28: 44077 | R28: =C26*$R$3+E26*(1-$R$3) -> 67.065787 | X28: 44077 | Y28: =C26*$Y$3+G26*(1-$Y$3) -> 15.338075 | AE28: 44077 | AF28: =C26*$AF$3+G26*(1-$AF$3) -> 13.878822
... A1302: 42284 | C1302: =-(Historical_Simulation!B1303-Historical_Simulation!B1304) -> 0.1325 | E1302: =-(Historical_Simulation!C1303-Historical_Simulation!C1304) -> -4.4599 | G1302: =-(Historical_Simulation!D1303-Historical_Simulation!D1304) -> 0.4 | J1302: 42286 | K1302: =C1300*$K$3+E1300*(1-$K$3) -> -3.8834454 | Q1302: 42286 | R1302: =C1300*$R$3+E1300*(1-$R$3) -> -2.8679876 | X1302: 42286 | Y1302: =C1300*$Y$3+G1300*(1-$Y$3) -> -1.2993523 | AE1302: 42286 | AF1302: =C1300*$AF$3+G1300*(1-$AF$3) -> -1.104197
J1303: 42285 | K1303: =C1301*$K$3+E1301*(1-$K$3) -> 4.8834405 | Q1303: 42285 | R1303: =C1301*$R$3+E1301*(1-$R$3) -> 3.4480806 | X1303: 42285 | Y1303: =C1301*$Y$3+G1301*(1-$Y$3) -> -1.8651949 | AE1303: 42285 | AF1303: =C1301*$AF$3+G1301*(1-$AF$3) -> -1.2033638
J1304: 42284 | K1304: =C1302*$K$3+E1302*(1-$K$3) -> -2.3447038 | Q1304: 42284 | R1304: =C1302*$R$3+E1302*(1-$R$3) -> -1.5655375 | X1304: 42284 | Y1304: =C1302*$Y$3+G1302*(1-$Y$3) -> 1.6313196 | AE1304: 42284 | AF1304: =C1302*$AF$3+G1302*(1-$AF$3) -> 1.1773713
